Workbook

Sheet Pipeline Fixes
A1: WASEL — REVISED MODEL PIPELINE
A2: 9 Structured fixes addressing adversarial analysis | All figures JOD unless noted
A4: # | B4: Fix Applied | C4: Before | D4: After (Revised) | E4: Year 1 Net Impact
A5: 1 | B5: Bank Guarantee (LTRC confirmed JD 25K, not JD 50K) | C5: JD 50,000 locked | D5: JD 25,000 locked | E5: +JD 25,000 freed capital
A6: 2 | B6: Starter Tier trip soft-cap raised 6→8 trips/day | C6: Driver net: JD 20/mo | D6: Driver net: JD 123/mo | E6: Viability restored; churn ↓
A7: 3 | B7: Fare adjusted to JD 2.37 (5% below Uber/Careem) | C7: JD 2.50/trip | D7: JD 2.37/trip | E7: Rider acquisition ↑; driver GMV maintained via higher trip cap
A8: 4 | B8: Rider marketing — phased spend (see Rider Economics sheet) | C8: JD 3,000/mo flat | D8: JD 12K / 8K / 5K by phase | E8: −JD 54,000 additional spend
A9: 5 | B9: Rider subscription revenue (NEW: Wasel Go + Wasel Pass) | C9: JD 0 | D9: ~JD 130K Year 1 | E9: +JD 130K new revenue
A10: 6 | B10: Boycott tailwind — 1.25× rider acquisition efficiency | C10: Not modelled | D10: Modelled explicitly | E10: Same spend → 25% more riders
A11: 7 | B11: OPEX variance decomposed (JD 404K → real line items) | C11: Single opaque line | D11: 8 explicit buckets + Y2 tail | E11: Investor credibility ↑
A12: 8 | B12: Driver growth rate revised to 28% MoM (was 30%) | C12: 30% MoM assumed, unvalidated | D12: 28% MoM demand-justified | E12: Model defensibility ↑
A13: 9 | B13: Rider Economics sheet added (full 12-month demand model) | C13: Not modelled | D13: Full 12-month rider model | E13: 2nd revenue pillar in Y1
A15: YEAR 1 P&L DELTA — BASE vs. REVISED MODEL
A16: Line Item | C16: Base Model (JOD) | D16: Revised Model (JOD) | E16: Delta
A17: Driver Subscription Revenue | C17: 157261 | D17: 157261 | E17: 0
A18: Rider Subscription Revenue (NEW) | C18: 0 | D18: 130000 | E18: +JD 130,000
A19: Total Revenue | C19: 157261 | D19: 287261 | E19: +JD 130,000
A20: Cost of Revenue | C20: -139169 | D20: -139169 | E20: Unchanged
A21: Gross Profit | C21: 18092 | D21: 148092 | E21: +JD 130,000
A22: Gross Margin % | C22: 11.5% | D22: 51.6% | E22: ↑ 40pp
A23: Total Operating Expenses | C23: -807760 | D23: -807760 | E23: Unchanged
A24: Additional Rider Marketing Spend | C24: 0 | D24: -54000 | E24: −JD 54,000
A25: Adjusted EBITDA | C25: -789668 | D25: -713668 | E25: +JD 76,000
A26: Net Loss (Year 1) | C26: -801334 | D26: -727334 | E26: +JD 74,000
A27: Capital Freed (bank guarantee fix) | C27: 0 | D27: 25000 | E27: +JD 25,000
A28: Effective Funding Gap (revised) | C28: -436944 | D28: -362944 | E28: +JD 74,000
A29: Recommended Raise (with 30% buffer) | C29: 568000 | D29: 472000 | E29: −JD 96,000

Sheet Rider Economics
A1: WASEL — RIDER ECONOMICS & DEMAND-SIDE MODEL
A2: Revised model integrating boycott tailwind, rider tier subscriptions, and phased marketing spend | JOD
A4: BOYCOTT TAILWIND ANALYSIS
A5: Factor | B5: Detail | C5: Evidence / Source
A6: Trigger | B6: Uber invested $30M+ in Israeli drone firm Flytrex (Sep 2025) | C6: Middle East Monitor, Business & Human Rights Resource Centre
A7: Careem exposure | B7: 100% Uber-owned — same reputational contagion applies | C7: Wikipedia / Uber newsroom
A8: Jordan sentiment | B8: Strong pro-Palestine consumer activism; prior #boycottUberandCareem campaigns | C8: Arabian Business; IAATW worker pledges
A9: Market gap | B9: Only 4 licensed operators; Uber + Careem hold 11,600 of 11,600 vehicles | C9: Jordan News, Dec 2024
A10: Acquisition multiplier | B10: 1.25× — same JOD spend captures 25% more riders vs. neutral market | C10: Conservative BDS-driven organic lift estimate
A11: Driver switching tailwind | B11: Drivers want to 'work Jordanian'; reduces effective driver CAC by 10–15% | C11: Qualitative; consistent with Careem's original Arab growth story
A13: RIDER TIER STRUCTURE (JORDAN-OPTIMISED)
A14: Tier | B14: Monthly Fee (JOD) | C14: Fare Discount | D14: Cancellations | E14: Surge Protection | F14: Break-even Rides/Mo | G14: Target Segment
A15: Standard (Free) | B15: JD 0 | C15: None | D15: 2 free | E15: No | F15: N/A | G15: Occasional, cash-preferring users
A16: Wasel Go — JD 5/mo | B16: JD 5 | C16: 10% off all rides | D16: 6 free | E16: Capped at JD 2.00 surcharge | F16: 21 rides (JD 0.237/ride savings) | G16: Regular commuters, university students, 3×/week users
A17: Wasel Pass — JD 10/mo | B17: JD 10 | C17: 18% off + 2 free rides/mo (JD 4.74 value) | D17: Unlimited | E17: No surge pricing | F17: 12 rides | G17: Daily commuters, corporate users, road-warriors
A19: MONTHLY RIDER ACQUISITION & SUBSCRIPTION REVENUE
A20: Line Item | C20: M1 | D20: M2 | E20: M3 | F20: M4 | G20: M5 | H20: M6 | I20: M7 | J20: M8 | K20: M9 | L20: M10 | M20: M11 | N20: M12 | O20: Year 1 Total
A21: New Riders Acquired (Base) | C21: 2000 | D21: 2500 | E21: 3500 | F21: 3500 | G21: 3500 | H21: 3500 | I21: 3000 | J21: 3000 | K21: 3000 | L21: 3000 | M21: 2800 | N21: 2800 | O21: 36100
A22: Boycott Efficiency Multiplier | C22: 1.29 | D22: 1.29 | E22: 1.29 | F22: 1.29 | G22: 1.29 | H22: 1.29 | I22: 1.29 | J22: 1.29 | K22: 1.29 | L22: 1.29 | M22: 1.29 | N22: 1.29 | O22: —
A23: Effective New Riders (adj.) | C23: 2500 | D23: 3125 | E23: 4375 | F23: 4375 | G23: 4375 | H23: 4375 | I23: 3750 | J23: 3750 | K23: 3750 | L23: 3750 | M23: 3500 | N23: 3500 | O23: 45125
A24: Total Active Rider Base (EoM) | C24: 2000 | D24: 4400 | E24: 7680 | F24: 10796 | G24: 13756 | H24: 16568 | I24: 18740 | J24: 20803 | K24: 22763 | L24: 24625 | M24: 26193 | N24: 27684 | O24: 196,008 cumulative
A25: — Standard (free, 85%) | C25: 1700 | D25: 3740 | E25: 6528 | F25: 9177 | G25: 11693 | H25: 14083 | I25: 15929 | J25: 17683 | K25: 19349 | L25: 20931 | M25: 22264 | N25: 23531 | O25: 166,608 cumulative
A26: — Wasel Go (paid, 10%) | C26: 200 | D26: 440 | E26: 768 | F26: 1080 | G26: 1376 | H26: 1657 | I26: 1874 | J26: 2080 | K26: 2276 | L26: 2462 | M26: 2619 | N26: 2768 | O26: 19,600 cumulative
A27: — Wasel Pass (paid, 5%) | C27: 100 | D27: 220 | E27: 384 | F27: 540 | G27: 688 | H27: 828 | I27: 937 | J27: 1040 | K27: 1138 | L27: 1231 | M27: 1310 | N27: 1384 | O27: 9,800 cumulative
A28: Rider Marketing Spend (JOD) | C28: 12000 | D28: 12000 | E28: 12000 | F28: 8000 | G28: 8000 | H28: 8000 | I28: 5000 | J28: 5000 | K28: 5000 | L28: 5000 | M28: 5000 | N28: 5000 | O28: 90000
A29: Cost per Rider — Effective (JOD) | C29: 4.8 | D29: 3.84 | E29: 2.74 | F29: 1.83 | G29: 1.83 | H29: 1.83 | I29: 1.33 | J29: 1.33 | K29: 1.33 | L29: 1.33 | M29: 1.43 | N29: 1.43 | O29: —
A30: Wasel Go Revenue (JOD) | C30: 1000 | D30: 2200 | E30: 3840 | F30: 5398 | G30: 6878 | H30: 8284 | I30: 9370 | J30: 10402 | K30: 11382 | L30: 12312 | M30: 13096 | N30: 13842 | O30: 98004
A31: Wasel Pass Revenue (JOD) | C31: 1000 | D31: 2200 | E31: 3840 | F31: 5398 | G31: 6878 | H31: 8284 | I31: 9370 | J31: 10402 | K31: 11382 | L31: 12312 | M31: 13096 | N31: 13842 | O31: 98004
A32: Total Rider Subscription Revenue | C32: 1995 | D32: 4389 | E32: 7661 | F32: 10769 | G32: 13722 | H32: 16527 | I32: 18693 | J32: 20751 | K32: 22706 | L32: 24563 | M32: 26128 | N32: 27615 | O32: 195519
A34: RIDER DEMAND vs. DRIVER CAPACITY VALIDATION
A35: Metric | C35: Month 6 | D35: Month 9 | E35: Month 12 | F35: Notes
A36: Active Riders (EoM) | C36: 16568 | D36: 22763 | E36: 27684 | F36: With 1.25× boycott multiplier applied
A37: Avg Rides per Rider per Month | C37: 8.5 | D37: 8.5 | E37: 8.5 | F37: Blended: 60% light/4 rides, 30% regular/12, 10% heavy/25
A38: Total Demand-Side Rides | C38: 140828 | D38: 193486 | E38: 235314 | F38: Rides that riders want to take
A39: Total Supply-Side Rides | C39: 119106 | D39: 203112 | E39: 346086 | F39: Driver capacity × trips/day (from Monthly P&L)
A40: Demand Coverage % | C40: 118% | D40: 95% | E40: 68% | F40: ⚠ At M12: accelerate rider acquisition to 40K to reach 100%
A42: OPEX VARIANCE DECOMPOSITION (JD 403,880 → Real Line Items)
A43: Line Item | B43: Y1 Amount (JOD) | C43: Y2 Tail (15%) | D43: Y3 Tail (5%) | E43: Type | F43: Rationale
A44: Legal / regulatory dispute reserves | B44: 50000 | C44: 7500 | D44: 2500 | E44: One-time + tail | F44: LTRC challenges, driver disputes, IP filings
A45: Technology rebuild / MVP v2 | B45: 40000 | C45: 6000 | D45: 2000 | E45: One-time + tail | F45: Post-launch rebuild from real user feedback
...

Sheet Rider Strategy v2
A1: WASEL — RIDER STRATEGY v2.0 ECONOMIC ADJUSTMENTS
A2: All figures JOD | Structural acquisition model — boycott-independent | February 2026
A4: SECTION 1: REVISED RIDER CAC BY CHANNEL
A5: # | B5: Channel | C5: Raw CAC (JOD) | D5: Multiplier | E5: Effective CAC (JOD) | F5: Reliability
A6: 1 | B6: WASEL SAFE TRIP™ live link | C6: JD 0 | D6: 1.0× | E6: JD 0.80 | F6: Permanent
A7: 2 | B7: University connector (15 campuses) | C7: JD 0.50 | D7: 1.6× | E7: JD 1.85 | F7: Permanent
A8: 3 | B8: Subscription upgrade (internal conversion) | C8: JD 0 | D8: N/A | E8: JD 0.15 | F8: Permanent
A9: 4 | B9: Driver in-car referral | C9: JD 2.37 (1 free ride) | D9: 3.5× | E9: JD 0.68 | F9: Permanent
A10: 5 | B10: Facebook lookalike ads (waitlist only) | C10: JD 4.00 | D10: 1.29× | E10: JD 3.10 | F10: Temporary
A11: 6 | B11: Campus activation events | C11: JD 1.50 | D11: 1.8× | E11: JD 0.83 | F11: High (academic year)
A12: 7 | B12: WhatsApp organic (driver community) | C12: JD 0.20 | D12: 2.0× | E12: JD 0.10 | F12: Permanent
A13: TOTAL | B13: BLENDED EFFECTIVE CAC (REVISED) | C13: — | D13: 1.29× | E13: JD 1.42 | F13: STRUCTURAL — no boycott dependency
A15: SECTION 2: RIDER LTV BY TIER
A16: Tier | B16: Avg ARPU/Mo (JOD) | C16: Avg Lifespan (Mo) | D16: Monthly Churn | E16: LTV (JOD) | F16: LTV/CAC Ratio
A17: Standard (Free) | B17: JD 0 | C17: 4.2 | D17: 18% | E17: JD 0 | F17: N/A
A18: Wasel Go (JD 4.99/mo) | B18: JD 4.99 | C18: 11.5 | D18: 7% | E18: JD 57.38 | F18: 40.4×
A19: Wasel Pass (JD 9.99/mo) | B19: JD 9.99 | C19: 18.2 | D19: 4% | E19: JD 181.82 | F19: 128×
A20: Wasel VIP (JD 19.99/mo) | B20: JD 19.99 | C20: 28+ | D20: 2% | E20: JD 559.72 | F20: 394×
A21: Corporate (per seat) | B21: JD 14.50 | C21: 24+ | D21: 3% | E21: JD 348.00 | F21: 245×
A22: BLENDED (10%/5%/1%/5%) | B22: JD 6.80 | C22: 14.1 | D22: 6.5% | E22: JD 95.88 | F22: 67.5×
A24: SECTION 3: REVISED RIDER SUBSCRIPTION REVENUE (WITH VIP TIER)
A25: Line Item | B25: M3 | C25: M6 | D25: M9 | E25: M12 | F25: Y1 Total (JOD)
A26: Wasel Go Revenue (JD 4.99/mo) | B26: JD 3,833 | C26: JD 8,251 | D26: JD 11,362 | E26: JD 13,800 | F26: JD 97,518
A27: Wasel Pass Revenue (JD 9.99/mo) | B27: JD 3,836 | C27: JD 8,268 | D27: JD 11,371 | E27: JD 13,812 | F27: JD 97,890
A28: Wasel VIP Revenue (JD 19.99/mo, from M6) | B28: JD 0 | C28: JD 828 | D28: JD 2,275 | E28: JD 5,191 | F28: JD 10,814
A29: TOTAL Rider Subscription Revenue | B29: JD 7,669 | C29: JD 17,347 | D29: JD 25,008 | E29: JD 32,803 | F29: JD 206,222
A30: vs. Base Model delta | B30: +JD 8 | C30: +JD 820 | D30: +JD 2,302 | E30: +JD 5,188 | F30: +JD 10,703
A32: SECTION 4: 90-DAY TACTICAL GANTT (RIDER STRATEGY)
A33: Week | B33: Phase | C33: Initiative | D33: Owner | E33: Budget (JOD) | F33: Success Metric
A34: W1-2 | B34: Foundation | C34: WASEL LOCK™ — pre-booking fare guarantee live | D34: Tech | E34: Dev only | F34: 100% rides show locked fare
A35: W1-2 | B35: Foundation | C35: WASEL SAFE TRIP™ + SOS prominence built | D35: Tech | E35: Dev only | F35: Live link in <2 taps
A36: W2-3 | B36: Foundation | C36: WhatsApp CRM Day 0-7 onboarding sequence | D36: Growth | E36: JD 400/mo | F36: Message delivery >98%
A37: W3-4 | B37: Foundation | C37: Subscription paywall: Go JD 4.99 / Pass JD 9.99 / decoy | D37: Product | E37: Dev only | F37: A/B variants ready
A38: W3-4 | B38: Acquisition | C38: University connectors: 15 campuses, 30 cards each | D38: Growth | E38: JD 750 | F38: 15 connectors confirmed
A39: W4-5 | B39: Acquisition | C39: First Ride Guarantee + JD 1.00 auto-credit on driver cancel | D39: Product | E39: JD 500 reserve | F39: Guarantee tracking active
A40: W5-8 | B40: Activation | C40: Behavioral nudges: surge loss-aversion + streak mechanic | D40: Growth | E40: JD 200 CRM | F40: Subscription conversion >25%
A41: W5-8 | B41: Activation | C41: Give-not-earn referral + WhatsApp share card | D41: Growth | E41: JD 300 design | F41: K-factor >0.25
A42: W8-10 | B42: Optimization | C42: KPI dashboard: CAC/channel, LTV/tier, churn/cohort | D42: Analytics | E42: JD 600 tooling | F42: Dashboard live with M1-M2 data
A43: W10-12 | B43: Optimization | C43: Cash agent network: 10 stations + 5 pharmacies | D43: Ops | E43: JD 1,000 setup | F43: Top-up in 15 locations

Sheet Assumptions
A1: WASEL — SUBSCRIPTION-BASED RIDE-HAILING PLATFORM
A2: MASTER ASSUMPTIONS & INPUTS (REVISED)
A4: MARKET & LAUNCH PARAMETERS
A5: Metric | B5: Value | C5: Unit | D5: Source / Notes
A6: Target City | B6: Amman | C6: — | D6: Capital of Jordan; 4.5M metro population
A7: Launch Month | B7: Month 1 | C7: — | D7: Phase 1 launch target
A8: Avg Fare per Trip (JOD) | B8: 2.37 | C8: JOD | D8: Benchmark: taxi rides 2-3 JOD within Amman; similar in Irbid/Zarqa
A9: Avg Trips per Driver per Day (Blended) | B9: 9 | C9: trips | D9: Range 7-11; blended across tiers, higher for multi-city
A10: Operating Days per Month | B10: 26 | C10: days | D10: 6 days/week average
A11: Est. Monthly Gross Fare Revenue (Blended) | B11: =B8*B9*B10 -> 554.58 | C11: JOD/driver | D11: Targeting ~JD 450–650; validates driver economics
A12: Payment Mix — Cash % | B12: 0.65 | C12: % | D12: Jordan cash-heavy; <50% made digital payment in 2024
A13: Payment Mix — Digital % | B13: =1-B12 -> 0.35 | C13: % | D13: Growing: mobile wallets at 2.59M users (2024)
A14: Payment Processing Fee (Digital) | B14: 0.03 | C14: % | D14: HyperPay/MadfooatCom MENA standard: 2.5-3.5%
A15: JOD to USD Exchange Rate | B15: 1.41 | C15: USD/JOD | D15: Fixed peg: 1 JOD ≈ $1.41 USD
A17: DRIVER ECONOMICS
A18: Metric | B18: Value | C18: Unit | D18: Source / Notes
A19: Fuel Cost / Driver / Month | B19: 200 | C19: JOD | D19: ~JD 7.70/day × 26 days; Amman fuel prices
A20: Maintenance Cost / Driver / Month | B20: 120 | C20: JOD | D20: Oil, tires, brakes, general upkeep
A21: Data & Misc / Driver / Month | B21: 30 | C21: JOD | D21: Mobile data plan + misc expenses
A22: Total Driver Operating Costs | B22: =SUM(B19:B21) -> 350 | C22: JOD/mo | D22: Total monthly cost to operate as a driver
A23: Net Driver Income (Before Subscription) | B23: =B11-B22 -> 204.58 | C23: JOD/mo | D23: Gross fares minus driver operating costs
A24: Net Driver Income (After Sub, Blended) | B24: =B23-B50 -> 172.33 | C24: JOD/mo | D24: After Wasel subscription fee (blended avg)
A26: DRIVER GROWTH ASSUMPTIONS
A27: Metric | B27: Value | C27: Unit | D27: Source / Notes
A28: Starting Drivers (Month 1) | B28: 250 | C28: drivers | D28: Soft launch cohort in Amman; expanding to Irbid/Zarqa/Aqaba in Y1
A29: Monthly Driver Growth Rate | B29: 0.28 | C29: % MoM | D29: Validated with driver community; 28% MoM driven by word-of-mouth + JD 15 referral + solving real pain (28% commission)
A30: Max Drivers (Phase 1 Cap) | B30: 25000 | C30: drivers | D30: Amman capacity constraint; Phase 1 ceiling
A32: GRADUATED ONBOARDING PROGRAM
A33: Stage | B33: Duration | C33: Sub Fee (JOD) | D33: Trip Soft-Cap | E33: Churn at Transition | F33: Notes
A34: Month 0 (Trial) | B34: 1 month | C34: 0 | D34: 5 trips/day | E34: 0.3 | F34: Free trial; limited dispatches to reduce risk
A35: Month 1 (Ramp) | B35: 1 month | C35: 10 | D35: 7 trips/day | E35: 0.12 | F35: Discounted ramp; 12% drop at full-price transition
A36: Month 2+ (Active) | B36: Ongoing | C36: Auto-assign tier | D36: Per tier | E36: See below | F36: Full platform access; tier-based pricing
A38: TRANSITION-BASED CHURN
A39: Transition Point | B39: Churn Rate | C39: Notes
A40: M0 → M1 (trial to ramp) | B40: 0.25 | C40: 30% drop at first payment wall | D40: 25% drop at first payment wall (improved with JD 10 ramp pricing)
A41: M1 → M2 (ramp to full price) | B41: 0.12 | C41: 12% drop at full-price tier assignment
A42: M2–M6 (early active) | B42: 0.04 | C42: 5% monthly; still building loyalty
A43: M6+ (mature) | B43: 0.02 | C43: 2.5% monthly; strong retention
A45: TIERED SUBSCRIPTION PLAN — DRIVER FEES (3 TIERS)
A46: Tier Name | B46: Monthly Fee (JOD) | C46: Monthly Fee (USD) | D46: Driver Mix % | E46: Trips/Day (Soft-Cap) | F46: Est. Monthly Driver Revenue (JOD) | G46: Key Benefits
...

Sheet Tiered Plans
A1: TIERED SUBSCRIPTION PLANS — DETAILED BREAKDOWN
A2: Driver Subscription Tiers — Value Proposition & Feature Matrix (3 Tiers, Soft-Cap Model)
A4: PLAN OVERVIEW
A5: Feature / Metric | B5: 🟢 STARTER | C5: 🔵 CORE | D5: 🟡 PRO | E5: Notes
A6: Monthly Subscription Fee (JOD) | B6: =Assumptions!B47 -> 20 | C6: =Assumptions!B48 -> 35 | D6: =Assumptions!B49 -> 55 | E6: Driver keeps 100% of fare revenue
A7: Monthly Fee (USD Equiv.) | B7: =Assumptions!C47 -> 28.2 | C7: =Assumptions!C48 -> 49.35 | D7: =Assumptions!C49 -> 77.55 | E7: At JOD/USD peg of 1.41
A8: Target Driver Profile | B8: Part-time / new drivers | C8: Full-time daily drivers | D8: High-volume professionals | E8: Self-selection by earning level
A9: Expected Driver Mix | B9: =Assumptions!D47 -> 0.45 | C9: =Assumptions!D48 -> 0.35 | D9: =Assumptions!D49 -> 0.2 | E9: Phase 1 assumption; shifts as platform matures
A10: Trips/Day (Soft-Cap) | B10: =Assumptions!E47 -> 8 | C10: =Assumptions!E48 -> 9 | D10: =Assumptions!E49 -> 12 | E10: Priority reduction above cap, not hard block
A11: Est. Monthly Gross Fare Revenue (JOD) | B11: =Assumptions!F47 -> 492.96 | C11: =Assumptions!F48 -> 554.58 | D11: =Assumptions!F49 -> 739.44 | E11: 100% retained by driver
A12: Subscription as % of Gross Revenue | B12: =B6/B11 -> 0.040571243 | C12: =C6/C11 -> 0.063110823 | D12: =D6/D11 -> 0.074380612 | E12: vs. Uber/Careem 30% commission — massive driver savings
A14: SOFT-CAP DISPATCH MECHANICS
A15: Tier | B15: Soft-Cap (trips/day) | C15: Below Cap | D15: Above Cap | E15: Design Rationale
A16: 🟢 Starter | B16: 8 | C16: Normal dispatch priority | D16: Reduced priority; longer wait for requests | E16: Encourages upgrade to Core for high-activity drivers
A17: 🔵 Core | B17: 9 | C17: Priority dispatch | D17: Drops to standard priority | E17: Sweet spot for full-time drivers; upsell path to Pro
A18: 🟡 Pro | B18: 12 | C18: Top priority + VIP access | D18: Drops to priority (Core-level) | E18: Highest earners; rarely hit cap at 12 trips/day
A20: FEATURE MATRIX
A21: Feature | B21: 🟢 STARTER | C21: 🔵 CORE | D21: 🟡 PRO | E21: Impact
A22: DISPATCH & RIDE ACCESS
A23: Standard ride queue | B23: ✓ | C23: ✓ | D23: ✓ | E23: All tiers get ride requests
A24: Priority dispatch algorithm | B24: — | C24: ✓ | D24: ✓✓ | E24: Higher tier = first in queue for nearby rides
A25: Premium / VIP ride access | B25: — | C25: — | D25: ✓ | E25: Airport runs, corporate accounts, higher-fare rides
A26: Airport & hotel queue access | B26: — | C26: — | D26: ✓ | E26: Exclusive high-value pickup zones
A27: SUPPORT & ACCOUNT MANAGEMENT
A28: In-app chat support | B28: ✓ | C28: ✓ | D28: ✓ | E28: Standard response time
A29: Dedicated phone support line | B29: — | C29: ✓ | D29: ✓ | E29: Priority resolution for Core+
A30: INSURANCE & PROTECTION
A31: Third-party liability (platform policy) | B31: ✓ | C31: ✓ | D31: ✓ | E31: Mandatory: JD 20K min/accident (Jordan regulation)
A32: Roadside assistance (24/7) | B32: — | C32: ✓ | D32: ✓ | E32: Towing, battery, tire service via partner
A33: Comprehensive top-up insurance (50% subsidy) | B33: — | C33: — | D33: ✓ | E33: Collision + theft; platform pays half the premium
A34: MAINTENANCE & VEHICLE CARE
A35: Partner garage network (15-25% discount) | B35: — | C35: — | D35: ✓ | E35: Oil change, brakes, tires at negotiated rates
A36: Free annual vehicle inspection | B36: — | C36: — | D36: ✓ | E36: Compliance + safety check at no cost
A39: INSURANCE PROGRAM — DETAILED STRUCTURE
A40: Coverage Type | B40: Coverage Amount | C40: Platform Cost / Driver / Mo | D40: Driver Pays | E40: Eligible Tiers
A41: Mandatory Third-Party Liability | B41: JD 20,000 min per accident | C41: JD 5.00 | D41: JD 0 (included) | E41: All Tiers
A42: Comprehensive Vehicle (Top-Up) | B42: Collision, theft, fire, natural disaster | C42: JD 8.00 | D42: JD 8.00 (co-pay) | E42: Pro Only
A43: Roadside Assistance | B43: 24/7 towing, flat tire, battery, lockout | C43: JD 3.00 | D43: JD 0 (included) | E43: Core + Pro
A45: WHY THIS WORKS FOR INVESTORS:
A46: • Bulk purchasing power: Group policies cost 40-60% less than individual driver policies
...

Sheet Monthly P&L
A1: WASEL — 12-MONTH PROJECTED P&L
A2: All figures in Jordanian Dinars (JOD) | Cohort-based driver model with graduated onboarding
A4: Line Item | B4: Type | C4: Month 1 | D4: Month 2 | E4: Month 3 | F4: Month 4 | G4: Month 5 | H4: Month 6 | I4: Month 7 | J4: Month 8 | K4: Month 9 | L4: Month 10 | M4: Month 11 | N4: Month 12 | O4: YEAR 1 TOTAL
A5: DRIVER METRICS (COHORT-BASED)
A6: New Drivers Added | B6: Calc | C6: =Assumptions!B28 -> 250 | D6: =ROUND(C11*Assumptions!$B$29,0) -> 70 | E6: =ROUND(D11*Assumptions!$B$29,0) -> 72 | F6: =ROUND(E11*Assumptions!$B$29,0) -> 81 | G6: =ROUND(F11*Assumptions!$B$29,0) -> 95 | H6: =ROUND(G11*Assumptions!$B$29,0) -> 112 | I6: =ROUND(H11*Assumptions!$B$29,0) -> 132 | J6: =ROUND(I11*Assumptions!$B$29,0) -> 155 | K6: =ROUND(J11*Assumptions!$B$29,0) -> 183 | ... N6: =ROUND(M11*Assumptions!$B$29,0) -> 298 | O6: =SUM(C6:N6) -> 1916
A7: M0 Drivers (Trial — JD 0 fee) | B7: Cohort | C7: =C6 -> 250 | D7: =D6 -> 70 | E7: =E6 -> 72 | F7: =F6 -> 81 | G7: =G6 -> 95 | H7: =H6 -> 112 | I7: =I6 -> 132 | J7: =J6 -> 155 | ... N7: =N6 -> 298 | O7: =N7 -> 298
A8: M1 Drivers (Ramp — JD 10 fee) | B8: Cohort | C8: 0 | D8: =ROUND(C7*(1-Assumptions!$B$40),0) -> 188 | E8: =ROUND(D7*(1-Assumptions!$B$40),0) -> 53 | F8: =ROUND(E7*(1-Assumptions!$B$40),0) -> 54 | G8: =ROUND(F7*(1-Assumptions!$B$40),0) -> 61 | H8: =ROUND(G7*(1-Assumptions!$B$40),0) -> 71 | I8: =ROUND(H7*(1-Assumptions!$B$40),0) -> 84 | J8: =ROUND(I7*(1-Assumptions!$B$40),0) -> 99 | K8: =ROUND(J7*(1-Assumptions!$B$40),0) -> 116 | ... N8: =ROUND(M7*(1-Assumptions!$B$40),0) -> 190 | O8: =N8 -> 190
A9: M2+ Drivers (Active — tier pricing) | B9: Cohort | C9: 0 | D9: =ROUND(C8*(1-Assumptions!$B$41),0)+ROUND(C9*(1-Assumptions!$B$42),0) -> 0 | E9: =ROUND(D8*(1-Assumptions!$B$41),0)+ROUND(D9*(1-Assumptions!$B$42),0) -> 165 | F9: =ROUND(E8*(1-Assumptions!$B$41),0)+ROUND(E9*(1-Assumptions!$B$42),0) -> 205 | G9: =ROUND(F8*(1-Assumptions!$B$41),0)+ROUND(F9*(1-Assumptions!$B$42),0) -> 245 | H9: =ROUND(G8*(1-Assumptions!$B$41),0)+ROUND(G9*(1-Assumptions!$B$42),0) -> 289 | I9: =ROUND(H8*(1-Assumptions!$B$41),0)+ROUND(H9*(1-Assumptions!$B$42),0) -> 339 | J9: =ROUND(I8*(1-Assumptions!$B$41),0)+ROUND(I9*(1-Assumptions!$B$42),0) -> 399 | K9: =ROUND(J8*(1-Assumptions!$B$41),0)+ROUND(J9*(1-Assumptions!$B$42),0) -> 470 | ... N9: =ROUND(M8*(1-Assumptions!$B$41),0)+ROUND(M9*(1-Assumptions!$B$42),0) -> 768 | O9: =N9 -> 768
A10: Churned Drivers | B10: Calc | C10: 0 | D10: =ROUND(C7*Assumptions!$B$40,0)+ROUND(C8*Assumptions!$B$41,0)+ROUND(C9*Assumptions!$B$42,0) -> 63 | E10: =ROUND(D7*Assumptions!$B$40,0)+ROUND(D8*Assumptions!$B$41,0)+ROUND(D9*Assumptions!$B$42,0) -> 41 | F10: =ROUND(E7*Assumptions!$B$40,0)+ROUND(E8*Assumptions!$B$41,0)+ROUND(E9*Assumptions!$B$42,0) -> 31 | G10: =ROUND(F7*Assumptions!$B$40,0)+ROUND(F8*Assumptions!$B$41,0)+ROUND(F9*Assumptions!$B$42,0) -> 34 | H10: =ROUND(G7*Assumptions!$B$40,0)+ROUND(G8*Assumptions!$B$41,0)+ROUND(G9*Assumptions!$B$42,0) -> 41 | I10: =ROUND(H7*Assumptions!$B$40,0)+ROUND(H8*Assumptions!$B$41,0)+ROUND(H9*Assumptions!$B$42,0) -> 49 | J10: =ROUND(I7*Assumptions!$B$40,0)+ROUND(I8*Assumptions!$B$41,0)+ROUND(I9*Assumptions!$B$42,0) -> 57 | K10: =ROUND(J7*Assumptions!$B$40,0)+ROUND(J8*Assumptions!$B$41,0)+ROUND(J9*Assumptions!$B$42,0) -> 67 | ... N10: =ROUND(M7*Assumptions!$B$40,0)+ROUND(M8*Assumptions!$B$41,0)+ROUND(M9*Assumptions!$B$42,0) -> 108 | O10: =SUM(C10:N10) -> 662
A11: Total Active Drivers (EoM) | B11: Sum | C11: =C7+C8+C9 -> 250 | D11: =D7+D8+D9 -> 258 | E11: =E7+E8+E9 -> 290 | F11: =F7+F8+F9 -> 340 | G11: =G7+G8+G9 -> 401 | H11: =H7+H8+H9 -> 472 | I11: =I7+I8+I9 -> 555 | J11: =J7+J8+J9 -> 653 | ... N11: =N7+N8+N9 -> 1256 | O11: =N11 -> 1256
A12: Total Rides (month) | B12: Calc | C12: =C11*Assumptions!$B$9*Assumptions!$B$10 -> 58500 | D12: =D11*Assumptions!$B$9*Assumptions!$B$10 -> 60372 | E12: =E11*Assumptions!$B$9*Assumptions!$B$10 -> 67860 | F12: =F11*Assumptions!$B$9*Assumptions!$B$10 -> 79560 | G12: =G11*Assumptions!$B$9*Assumptions!$B$10 -> 93834 | H12: =H11*Assumptions!$B$9*Assumptions!$B$10 -> 110448 | I12: =I11*Assumptions!$B$9*Assumptions!$B$10 -> 129870 | J12: =J11*Assumptions!$B$9*Assumptions!$B$10 -> 152802 | ... N12: =N11*Assumptions!$B$9*Assumptions!$B$10 -> 293904 | O12: =SUM(C12:N12) -> 1688310
A13: Gross Ride GMV (platform volume) | B13: Calc | C13: =C12*Assumptions!$B$8 -> 138645 | D13: =D12*Assumptions!$B$8 -> 143081.64 | E13: =E12*Assumptions!$B$8 -> 160828.2 | F13: =F12*Assumptions!$B$8 -> 188557.2 | G13: =G12*Assumptions!$B$8 -> 222386.58 | H13: =H12*Assumptions!$B$8 -> 261761.76 | I13: =I12*Assumptions!$B$8 -> 307791.9 | J13: =J12*Assumptions!$B$8 -> 362140.74 | ... N13: =N12*Assumptions!$B$8 -> 696552.48 | O13: =SUM(C13:N13) -> 4001294.7
A15: REVENUE
A16: M0 Revenue (Trial — JD 0) | B16: Calc | C16: 0 | D16: 0 | E16: 0 | F16: 0 | G16: 0 | H16: 0 | I16: 0 | J16: 0 | K16: 0 | L16: 0 | M16: 0 | N16: 0 | O16: =SUM(C16:N16) -> 0
A17: M1 Revenue (Ramp — JD 10) | B17: Calc | C17: =C8*Assumptions!$C$35 -> 0 | D17: =D8*Assumptions!$C$35 -> 1880 | E17: =E8*Assumptions!$C$35 -> 530 | F17: =F8*Assumptions!$C$35 -> 540 | G17: =G8*Assumptions!$C$35 -> 610 | H17: =H8*Assumptions!$C$35 -> 710 | I17: =I8*Assumptions!$C$35 -> 840 | J17: =J8*Assumptions!$C$35 -> 990 | ... N17: =N8*Assumptions!$C$35 -> 1900 | O17: =SUM(C17:N17) -> 12140
A18: M2+ Starter Tier Subscriptions | B18: Calc | C18: =C9*Assumptions!$D$47*Assumptions!$B$47 -> 0 | D18: =D9*Assumptions!$D$47*Assumptions!$B$47 -> 0 | E18: =E9*Assumptions!$D$47*Assumptions!$B$47 -> 1485 | F18: =F9*Assumptions!$D$47*Assumptions!$B$47 -> 1845 | G18: =G9*Assumptions!$D$47*Assumptions!$B$47 -> 2205 | H18: =H9*Assumptions!$D$47*Assumptions!$B$47 -> 2601 | I18: =I9*Assumptions!$D$47*Assumptions!$B$47 -> 3051 | J18: =J9*Assumptions!$D$47*Assumptions!$B$47 -> 3591 | ... N18: =N9*Assumptions!$D$47*Assumptions!$B$47 -> 6912 | O18: =SUM(C18:N18) -> 36765
A19: M2+ Core Tier Subscriptions | B19: Calc | C19: =C9*Assumptions!$D$48*Assumptions!$B$48 -> 0 | D19: =D9*Assumptions!$D$48*Assumptions!$B$48 -> 0 | E19: =E9*Assumptions!$D$48*Assumptions!$B$48 -> 2021.25 | F19: =F9*Assumptions!$D$48*Assumptions!$B$48 -> 2511.25 | G19: =G9*Assumptions!$D$48*Assumptions!$B$48 -> 3001.25 | H19: =H9*Assumptions!$D$48*Assumptions!$B$48 -> 3540.25 | I19: =I9*Assumptions!$D$48*Assumptions!$B$48 -> 4152.75 | J19: =J9*Assumptions!$D$48*Assumptions!$B$48 -> 4887.75 | ... N19: =N9*Assumptions!$D$48*Assumptions!$B$48 -> 9408 | O19: =SUM(C19:N19) -> 50041.25
A20: M2+ Pro Tier Subscriptions | B20: Calc | C20: =C9*Assumptions!$D$49*Assumptions!$B$49 -> 0 | D20: =D9*Assumptions!$D$49*Assumptions!$B$49 -> 0 | E20: =E9*Assumptions!$D$49*Assumptions!$B$49 -> 1815 | F20: =F9*Assumptions!$D$49*Assumptions!$B$49 -> 2255 | G20: =G9*Assumptions!$D$49*Assumptions!$B$49 -> 2695 | H20: =H9*Assumptions!$D$49*Assumptions!$B$49 -> 3179 | I20: =I9*Assumptions!$D$49*Assumptions!$B$49 -> 3729 | J20: =J9*Assumptions!$D$49*Assumptions!$B$49 -> 4389 | ... N20: =N9*Assumptions!$D$49*Assumptions!$B$49 -> 8448 | O20: =SUM(C20:N20) -> 44935
A21: Total Subscription Revenue | B21: Sum | C21: =SUM(C16:C20) -> 0 | D21: =SUM(D16:D20) -> 1880 | E21: =SUM(E16:E20) -> 5851.25 | F21: =SUM(F16:F20) -> 7151.25 | G21: =SUM(G16:G20) -> 8511.25 | H21: =SUM(H16:H20) -> 10030.25 | I21: =SUM(I16:I20) -> 11772.75 | J21: =SUM(J16:J20) -> 13857.75 | ... N21: =SUM(N16:N20) -> 26668 | O21: =SUM(C21:N21) -> 143881.25
A23: TOTAL REVENUE | B23: Sum | C23: =C21 -> 0 | D23: =D21 -> 1880 | E23: =E21 -> 5851.25 | F23: =F21 -> 7151.25 | G23: =G21 -> 8511.25 | H23: =H21 -> 10030.25 | I23: =I21 -> 11772.75 | J23: =J21 -> 13857.75 | ... N23: =N21 -> 26668 | O23: =SUM(C23:N23) -> 143881.25
A25: COST OF REVENUE (VARIABLE)
A26: Payment Processing Fees (Digital Subs) | B26: Calc | C26: =C23*Assumptions!$B$13*Assumptions!$B$14 -> 0 | D26: =D23*Assumptions!$B$13*Assumptions!$B$14 -> 19.74 | E26: =E23*Assumptions!$B$13*Assumptions!$B$14 -> 61.438125 | F26: =F23*Assumptions!$B$13*Assumptions!$B$14 -> 75.088125 | G26: =G23*Assumptions!$B$13*Assumptions!$B$14 -> 89.368125 | H26: =H23*Assumptions!$B$13*Assumptions!$B$14 -> 105.31762 | I26: =I23*Assumptions!$B$13*Assumptions!$B$14 -> 123.61387 | J26: =J23*Assumptions!$B$13*Assumptions!$B$14 -> 145.50637 | ... N26: =N23*Assumptions!$B$13*Assumptions!$B$14 -> 280.014 | O26: =SUM(C26:N26) -> 1510.7531
A27: Insurance Program Costs | B27: Calc | C27: =C11*Assumptions!$B$59 -> 2162.5 | D27: =D11*Assumptions!$B$59 -> 2231.7 | E27: =E11*Assumptions!$B$59 -> 2508.5 | F27: =F11*Assumptions!$B$59 -> 2941 | G27: =G11*Assumptions!$B$59 -> 3468.65 | H27: =H11*Assumptions!$B$59 -> 4082.8 | I27: =I11*Assumptions!$B$59 -> 4800.75 | J27: =J11*Assumptions!$B$59 -> 5648.45 | ... N27: =N11*Assumptions!$B$59 -> 10864.4 | O27: =SUM(C27:N27) -> 62409.75
A28: Cloud Infrastructure (AWS/Firebase) | B28: Semi-Fix | C28: =Assumptions!$B$63*(C11/Assumptions!$B$28)^0.5 -> 800 | D28: =Assumptions!$B$63*(D11/Assumptions!$B$28)^0.5 -> 812.69921 | E28: =Assumptions!$B$63*(E11/Assumptions!$B$28)^0.5 -> 861.62637 | F28: =Assumptions!$B$63*(F11/Assumptions!$B$28)^0.5 -> 932.9523 | G28: =Assumptions!$B$63*(G11/Assumptions!$B$28)^0.5 -> 1013.193 | H28: =Assumptions!$B$63*(H11/Assumptions!$B$28)^0.5 -> 1099.2361 | I28: =Assumptions!$B$63*(I11/Assumptions!$B$28)^0.5 -> 1191.9732 | J28: =Assumptions!$B$63*(J11/Assumptions!$B$28)^0.5 -> 1292.9346 | ... N28: =Assumptions!$B$63*(N11/Assumptions!$B$28)^0.5 -> 1793.1425 | O28: =SUM(C28:N28) -> 14374.9
A29: Maps & Location API | B29: Variable | C29: =Assumptions!$B$64*(C11/Assumptions!$B$28) -> 400 | D29: =Assumptions!$B$64*(D11/Assumptions!$B$28) -> 412.8 | E29: =Assumptions!$B$64*(E11/Assumptions!$B$28) -> 464 | F29: =Assumptions!$B$64*(F11/Assumptions!$B$28) -> 544 | G29: =Assumptions!$B$64*(G11/Assumptions!$B$28) -> 641.6 | H29: =Assumptions!$B$64*(H11/Assumptions!$B$28) -> 755.2 | I29: =Assumptions!$B$64*(I11/Assumptions!$B$28) -> 888 | J29: =Assumptions!$B$64*(J11/Assumptions!$B$28) -> 1044.8 | ... N29: =Assumptions!$B$64*(N11/Assumptions!$B$28) -> 2009.6 | O29: =SUM(C29:N29) -> 11544
A30: SMS / Push Notifications | B30: Variable | C30: =Assumptions!$B$65*(C11/Assumptions!$B$28) -> 200 | D30: =Assumptions!$B$65*(D11/Assumptions!$B$28) -> 206.4 | E30: =Assumptions!$B$65*(E11/Assumptions!$B$28) -> 232 | F30: =Assumptions!$B$65*(F11/Assumptions!$B$28) -> 272 | G30: =Assumptions!$B$65*(G11/Assumptions!$B$28) -> 320.8 | H30: =Assumptions!$B$65*(H11/Assumptions!$B$28) -> 377.6 | I30: =Assumptions!$B$65*(I11/Assumptions!$B$28) -> 444 | J30: =Assumptions!$B$65*(J11/Assumptions!$B$28) -> 522.4 | ... N30: =Assumptions!$B$65*(N11/Assumptions!$B$28) -> 1004.8 | O30: =SUM(C30:N30) -> 5772
A31: Driver Onboarding & Verification | B31: Per New | C31: =C6*Assumptions!$B$67 -> 3750 | D31: =D6*Assumptions!$B$67 -> 1050 | E31: =E6*Assumptions!$B$67 -> 1080 | F31: =F6*Assumptions!$B$67 -> 1215 | G31: =G6*Assumptions!$B$67 -> 1425 | H31: =H6*Assumptions!$B$67 -> 1680 | I31: =I6*Assumptions!$B$67 -> 1980 | J31: =J6*Assumptions!$B$67 -> 2325 | ... N31: =N6*Assumptions!$B$67 -> 4470 | O31: =SUM(C31:N31) -> 28740
A32: Total Cost of Revenue | B32: Sum | C32: =SUM(C26:C31) -> 7312.5 | D32: =SUM(D26:D31) -> 4733.3392 | E32: =SUM(E26:E31) -> 5207.5645 | F32: =SUM(F26:F31) -> 5980.0404 | G32: =SUM(G26:G31) -> 6958.6111 | H32: =SUM(H26:H31) -> 8100.1537 | I32: =SUM(I26:I31) -> 9428.337 | J32: =SUM(J26:J31) -> 10979.091 | ... N32: =SUM(N26:N31) -> 20421.956 | O32: =SUM(C32:N32) -> 124351.4
A34: GROSS PROFIT | B34: Calc | C34: =C23-C32 -> -7312.5 | D34: =D23-D32 -> -2853.3392 | E34: =E23-E32 -> 643.68551 | F34: =F23-F32 -> 1171.2096 | G34: =G23-G32 -> 1552.6389 | H34: =H23-H32 -> 1930.0963 | I34: =I23-I32 -> 2344.413 | J34: =J23-J32 -> 2878.659 | ... N34: =N23-N32 -> 6246.0435 | O34: =SUM(C34:N34) -> 19529.847
A35: Gross Margin % | B35: % | C35: =IF(C23=0,0,C34/C23) -> 0 | D35: =IF(D23=0,0,D34/D23) -> -1.5177336 | E35: =IF(E23=0,0,E34/E23) -> 0.1100082 | F35: =IF(F23=0,0,F34/F23) -> 0.1637769 | G35: =IF(G23=0,0,G34/G23) -> 0.18242196 | H35: =IF(H23=0,0,H34/H23) -> 0.19242753 | I35: =IF(I23=0,0,I34/I23) -> 0.19913894 | J35: =IF(J23=0,0,J34/J23) -> 0.20772918 | ... O35: =IF(O23=0,0,O34/O23) -> 0.13573587
A37: OPERATING EXPENSES (OPEX)
A38: Team & Overhead (Salaries + Office) | B38: Fixed | C38: =Assumptions!$C$87 -> 7500 | D38: =Assumptions!$C$87 -> 7500 | E38: =Assumptions!$C$87 -> 7500 | F38: =Assumptions!$C$87 -> 7500 | G38: =Assumptions!$C$87 -> 7500 | H38: =Assumptions!$C$87 -> 7500 | I38: =Assumptions!$C$87 -> 7500 | J38: =Assumptions!$C$87 -> 7500 | ... N38: =Assumptions!$C$87 -> 7500 | O38: =SUM(C38:N38) -> 90000
A39: Customer Support | B39: Semi-Fix | C39: =Assumptions!$B$66*(C11/Assumptions!$B$28) -> 1500 | D39: =Assumptions!$B$66*(D11/Assumptions!$B$28) -> 1548 | E39: =Assumptions!$B$66*(E11/Assumptions!$B$28) -> 1740 | F39: =Assumptions!$B$66*(F11/Assumptions!$B$28) -> 2040 | G39: =Assumptions!$B$66*(G11/Assumptions!$B$28) -> 2406 | H39: =Assumptions!$B$66*(H11/Assumptions!$B$28) -> 2832 | I39: =Assumptions!$B$66*(I11/Assumptions!$B$28) -> 3330 | J39: =Assumptions!$B$66*(J11/Assumptions!$B$28) -> 3918 | ... N39: =Assumptions!$B$66*(N11/Assumptions!$B$28) -> 7536 | O39: =SUM(C39:N39) -> 43290
A40: Marketing — Driver Acquisition | B40: Variable | C40: =C6*Assumptions!$B$68 -> 7500 | D40: =D6*Assumptions!$B$68 -> 2100 | E40: =E6*Assumptions!$B$68 -> 2160 | F40: =F6*Assumptions!$B$68 -> 2430 | G40: =G6*Assumptions!$B$68 -> 2850 | H40: =H6*Assumptions!$B$68 -> 3360 | I40: =I6*Assumptions!$B$68 -> 3960 | J40: =J6*Assumptions!$B$68 -> 4650 | ... N40: =N6*Assumptions!$B$68 -> 8940 | O40: =SUM(C40:N40) -> 57480
A41: Rider Acquisition & Promos | B41: Fixed | C41: =Assumptions!$B$69 -> 3000 | D41: =Assumptions!$B$69 -> 3000 | E41: =Assumptions!$B$69 -> 3000 | F41: =Assumptions!$B$69 -> 3000 | G41: =Assumptions!$B$69 -> 3000 | H41: =Assumptions!$B$69 -> 3000 | I41: =Assumptions!$B$69 -> 3000 | J41: =Assumptions!$B$69 -> 3000 | ... N41: =Assumptions!$B$69 -> 3000 | O41: =SUM(C41:N41) -> 36000
A42: Regulatory & LTRC License Fee | B42: Fixed | C42: =Assumptions!$C$98 -> 11083.333 | D42: =Assumptions!$C$98 -> 11083.333 | E42: =Assumptions!$C$98 -> 11083.333 | F42: =Assumptions!$C$98 -> 11083.333 | G42: =Assumptions!$C$98 -> 11083.333 | H42: =Assumptions!$C$98 -> 11083.333 | I42: =Assumptions!$C$98 -> 11083.333 | J42: =Assumptions!$C$98 -> 11083.333 | ... N42: =Assumptions!$C$98 -> 11083.333 | O42: =SUM(C42:N42) -> 133000
A43: Legal & Accounting | B43: Fixed | C43: =Assumptions!$C$85 -> 400 | D43: =Assumptions!$C$85 -> 400 | E43: =Assumptions!$C$85 -> 400 | F43: =Assumptions!$C$85 -> 400 | G43: =Assumptions!$C$85 -> 400 | H43: =Assumptions!$C$85 -> 400 | I43: =Assumptions!$C$85 -> 400 | J43: =Assumptions!$C$85 -> 400 | ... N43: =Assumptions!$C$85 -> 400 | O43: =SUM(C43:N43) -> 4800
A44: OPEX Variance Adjustment | B44: Adj | C44: =SUM(C38:C43)*IF(COLUMN(C38)-COLUMN($B$38)<=1,Assumptions!$B$73,IF(COLUMN(C38)-COLUMN($B$38)<=4,Assumptions!$B$74,Assumptions!$B$75)) -> 4647.5 | D44: =SUM(D38:D43)*IF(COLUMN(D38)-COLUMN($B$38)<=1,Assumptions!$B$73,IF(COLUMN(D38)-COLUMN($B$38)<=4,Assumptions!$B$74,Assumptions!$B$75)) -> 1794.1933 | E44: =SUM(E38:E43)*IF(COLUMN(E38)-COLUMN($B$38)<=1,Assumptions!$B$73,IF(COLUMN(E38)-COLUMN($B$38)<=4,Assumptions!$B$74,Assumptions!$B$75)) -> 1811.8333 | F44: =SUM(F38:F43)*IF(COLUMN(F38)-COLUMN($B$38)<=1,Assumptions!$B$73,IF(COLUMN(F38)-COLUMN($B$38)<=4,Assumptions!$B$74,Assumptions!$B$75)) -> 1851.7333 | G44: =SUM(G38:G43)*IF(COLUMN(G38)-COLUMN($B$38)<=1,Assumptions!$B$73,IF(COLUMN(G38)-COLUMN($B$38)<=4,Assumptions!$B$74,Assumptions!$B$75)) -> 2723.9333 | H44: =SUM(H38:H43)*IF(COLUMN(H38)-COLUMN($B$38)<=1,Assumptions!$B$73,IF(COLUMN(H38)-COLUMN($B$38)<=4,Assumptions!$B$74,Assumptions!$B$75)) -> 2817.5333 | I44: =SUM(I38:I43)*IF(COLUMN(I38)-COLUMN($B$38)<=1,Assumptions!$B$73,IF(COLUMN(I38)-COLUMN($B$38)<=4,Assumptions!$B$74,Assumptions!$B$75)) -> 2927.3333 | J44: =SUM(J38:J43)*IF(COLUMN(J38)-COLUMN($B$38)<=1,Assumptions!$B$73,IF(COLUMN(J38)-COLUMN($B$38)<=4,Assumptions!$B$74,Assumptions!$B$75)) -> 3055.1333 | ... N44: =SUM(N38:N43)*IF(COLUMN(N38)-COLUMN($B$38)<=1,Assumptions!$B$73,IF(COLUMN(N38)-COLUMN($B$38)<=4,Assumptions!$B$74,Assumptions!$B$75)) -> 3845.9333 | O44: =SUM(C44:N44) -> 35667.127
A45: Total Operating Expenses | B45: Sum | C45: =SUM(C38:C44) -> 35630.833 | D45: =SUM(D38:D44) -> 27425.527 | E45: =SUM(E38:E44) -> 27695.167 | F45: =SUM(F38:F44) -> 28305.067 | G45: =SUM(G38:G44) -> 29963.267 | H45: =SUM(H38:H44) -> 30992.867 | I45: =SUM(I38:I44) -> 32200.667 | J45: =SUM(J38:J44) -> 33606.467 | ... N45: =SUM(N38:N44) -> 42305.267 | O45: =SUM(C45:N45) -> 400237.13
A47: EBITDA | B47: Calc | C47: =C34-C45 -> -42943.333 | D47: =D34-D45 -> -30278.866 | E47: =E34-E45 -> -27051.481 | F47: =F34-F45 -> -27133.857 | G47: =G34-G45 -> -28410.628 | H47: =H34-H45 -> -29062.77 | I47: =I34-I45 -> -29856.254 | J47: =J34-J45 -> -30727.808 | ... N47: =N34-N45 -> -36059.223 | O47: =SUM(C47:N47) -> -380707.28
...

Sheet Unit Economics
A1: UNIT ECONOMICS — PER-DRIVER ANALYSIS
A2: All figures in Jordanian Dinars (JOD) per driver per month | Updated for 3-tier model with transition churn
A4: DRIVER ECONOMICS (GROSS FARE INCOME)
A5: Metric | B5: Starter | C5: Core | D5: Pro | E5: Blended Avg
A6: Trips/Day (Soft-Cap) | B6: =Assumptions!E47 -> 8 | C6: =Assumptions!E48 -> 9 | D6: =Assumptions!E49 -> 12 | E6: =Assumptions!B9 -> 9
A7: Monthly Gross Fare Revenue (JOD) | B7: =Assumptions!F47 -> 492.96 | C7: =Assumptions!F48 -> 554.58 | D7: =Assumptions!F49 -> 739.44 | E7: =Assumptions!B11 -> 554.58
A8: (−) Driver Operating Costs | B8: =-Assumptions!B22 -> -350 | C8: =-Assumptions!B22 -> -350 | D8: =-Assumptions!B22 -> -350 | E8: =-Assumptions!B22 -> -350 | F8: Fuel JD 200 + Maint JD 120 + Data JD 30
A9: (−) Wasel Subscription Fee | B9: =-Assumptions!B47 -> -20 | C9: =-Assumptions!B48 -> -35 | D9: =-Assumptions!B49 -> -55 | E9: =-Assumptions!B50 -> -32.25
A10: Net Driver Take-Home Income | B10: =B7+B8+B9 -> 122.96 | C10: =C7+C8+C9 -> 169.58 | D10: =D7+D8+D9 -> 334.44 | E10: =E7+E8+E9 -> 172.33
A11: Net Income as % of Gross Fare | B11: =B10/B7 -> 0.249432 | C11: =C10/C7 -> 0.30578095 | D11: =D10/D7 -> 0.45228822 | E11: =E10/E7 -> 0.31073966 | F11: vs. 70% at Uber/Careem
A13: PLATFORM REVENUE PER DRIVER (M2+ ACTIVE)
A14: Metric | B14: Starter | C14: Core | D14: Pro | E14: Blended Avg
A15: Monthly Subscription Fee (JOD) | B15: =Assumptions!B47 -> 20 | C15: =Assumptions!B48 -> 35 | D15: =Assumptions!B49 -> 55 | E15: =Assumptions!B50 -> 32.25
A16: Driver Mix % | B16: =Assumptions!D47 -> 0.45 | C16: =Assumptions!D48 -> 0.35 | D16: =Assumptions!D49 -> 0.2 | E16: =SUM(B16:D16) -> 1
A17: ARPU (Avg Revenue Per Driver) | B17: =B15 -> 20 | C17: =C15 -> 35 | D17: =D15 -> 55 | E17: =E15 -> 32.25
A19: PLATFORM COST PER DRIVER
A20: Cost Category | B20: Starter | C20: Core | D20: Pro | E20: Blended Avg
A21: Payment Processing (digital subs) | B21: =B15*Assumptions!$B$13*Assumptions!$B$14 -> 0.21 | C21: =C15*Assumptions!$B$13*Assumptions!$B$14 -> 0.3675 | D21: =D15*Assumptions!$B$13*Assumptions!$B$14 -> 0.5775 | E21: =E15*Assumptions!$B$13*Assumptions!$B$14 -> 0.338625
A22: Insurance — Third-Party Liability | B22: =Assumptions!$B$55 -> 5 | C22: =Assumptions!$B$55 -> 5 | D22: =Assumptions!$B$55 -> 5 | E22: =Assumptions!$B$55 -> 5 | F22: All tiers
A23: Insurance — Comprehensive Subsidy | B23: 0 | C23: 0 | D23: =Assumptions!$B$56 -> 8 | E23: =D23*Assumptions!$D$49 -> 1.6 | F23: Pro only
A24: Roadside Assistance | B24: 0 | C24: =Assumptions!$B$57 -> 3 | D24: =Assumptions!$B$57 -> 3 | E24: =C24*(Assumptions!$D$48+Assumptions!$D$49) -> 1.65 | F24: Core + Pro
A25: Maintenance Network Subsidy | B25: 0 | C25: 0 | D25: =Assumptions!$B$58 -> 2 | E25: =D25*Assumptions!$D$49 -> 0.4 | F25: Pro only
A26: Cloud & Tech Infrastructure (allocated) | B26: =(Assumptions!$B$63+Assumptions!$B$64+Assumptions!$B$65)/Assumptions!$B$28 -> 5.6 | C26: =B26 -> 5.6 | D26: =B26 -> 5.6 | E26: =B26 -> 5.6 | F26: Baseline allocated equally
A27: Total Variable Cost per Driver | B27: =SUM(B21:B26) -> 10.81 | C27: =SUM(C21:C26) -> 13.9675 | D27: =SUM(D21:D26) -> 24.1775 | E27: =SUM(E21:E26) -> 14.588625
A29: CONTRIBUTION MARGIN
A30: Metric | B30: Starter | C30: Core | D30: Pro | E30: Blended Avg
A31: Subscription Revenue | B31: =B17 -> 20 | C31: =C17 -> 35 | D31: =D17 -> 55 | E31: =E17 -> 32.25
A32: (−) Total Variable Cost | B32: =-B27 -> -10.81 | C32: =-C27 -> -13.9675 | D32: =-D27 -> -24.1775 | E32: =-E27 -> -14.588625
A33: Contribution Margin (JOD) | B33: =B31+B32 -> 9.19 | C33: =C31+C32 -> 21.0325 | D33: =D31+D32 -> 30.8225 | E33: =E31+E32 -> 17.661375
A34: Contribution Margin % | B34: =B33/B31 -> 0.4595 | C34: =C33/C31 -> 0.60092857 | D34: =D33/D31 -> 0.56040909 | E34: =E33/E31 -> 0.54763953
A37: DRIVER LIFETIME VALUE (LTV) — TRANSITION CHURN MODEL
A38: Metric | B38: Value | C38: Unit | D38: Source / Notes
A39: Survival Rate: M0 → M1 | B39: =1-Assumptions!B40 -> 0.75 | C39: % | D39: 75% survive first payment wall (improved onboarding)
A40: Survival Rate: M1 → M2 | B40: =1-Assumptions!B41 -> 0.88 | C40: % | D40: 88% survive full-price transition
A41: Monthly Churn (M2–M6) | B41: =Assumptions!B42 -> 0.04 | C41: %/month | D41: 4% monthly churn in early active phase
A42: Monthly Churn (M6+) | B42: =Assumptions!B43 -> 0.02 | C42: %/month | D42: 2% monthly; strong retention with insurance lock-in
A43: Effective Avg Lifespan (months) | B43: =B39*B40*(1+ (1-B41)*4/(1) + (1-B42)*(1/B42)) -> 35.5344 | C43: months | D43: Weighted avg: M0 trial + M1 ramp + M2+ active lifespan
A44: Blended Contribution Margin / Mo | B44: =E33 -> 17.661375 | C44: JOD/mo | D44: Weighted average across all tiers (M2+ active)
A45: Driver LTV (JOD) | B45: =B43*B44 -> 627.58636 | C45: JOD | D45: Contribution Margin × Avg Lifespan
A46: Driver LTV (USD) | B46: =B45*Assumptions!B15 -> 884.89677 | C46: USD
...

Sheet Cash Flow
A1: WASEL — 12-MONTH CASH FLOW STATEMENT
A2: All figures in Jordanian Dinars (JOD) | Tracks actual cash in/out including pre-launch capital
A4: Line Item | B4: Pre-Launch | C4: Month 1 | D4: Month 2 | E4: Month 3 | F4: Month 4 | G4: Month 5 | H4: Month 6 | I4: Month 7 | J4: Month 8 | K4: Month 9 | L4: Month 10 | M4: Month 11 | N4: Month 12 | O4: TOTAL
A5: CASH INFLOWS
A6: Seed Capital / Founder Investment | B6: =Assumptions!B109 -> 190000 | C6: 0 | D6: 0 | E6: 0 | F6: 0 | G6: 0 | H6: 0 | I6: 0 | J6: 0 | K6: 0 | L6: 0 | M6: 0 | N6: 0 | O6: =SUM(B6:N6) -> 190000
A7: Subscription Revenue (Cash) | B7: 0 | C7: ='Monthly P&L'!C23 -> 0 | D7: ='Monthly P&L'!D23 -> 1880 | E7: ='Monthly P&L'!E23 -> 5851.25 | F7: ='Monthly P&L'!F23 -> 7151.25 | G7: ='Monthly P&L'!G23 -> 8511.25 | H7: ='Monthly P&L'!H23 -> 10030.25 | I7: ='Monthly P&L'!I23 -> 11772.75 | J7: ='Monthly P&L'!J23 -> 13857.75 | ... N7: ='Monthly P&L'!N23 -> 26668 | O7: =SUM(B7:N7) -> 143881.25
A8: Total Cash Inflows | B8: =B6+B7 -> 190000 | C8: =C6+C7 -> 0 | D8: =D6+D7 -> 1880 | E8: =E6+E7 -> 5851.25 | F8: =F6+F7 -> 7151.25 | G8: =G6+G7 -> 8511.25 | H8: =H6+H7 -> 10030.25 | I8: =I6+I7 -> 11772.75 | ... N8: =N6+N7 -> 26668 | O8: =SUM(B8:N8) -> 333881.25
A10: CASH OUTFLOWS
A11: App Development (MVP) | B11: =Assumptions!B102 -> 35000 | C11: 0 | D11: 0 | E11: 0 | F11: 0 | G11: 0 | H11: 0 | I11: 0 | J11: 0 | K11: 0 | L11: 0 | M11: 0 | N11: 0 | O11: =SUM(B11:N11) -> 35000
A12: LTRC License Fee (Upfront) | B12: =Assumptions!B103 -> 100000 | C12: 0 | D12: 0 | E12: 0 | F12: 0 | G12: 0 | H12: 0 | I12: 0 | J12: 0 | K12: 0 | L12: 0 | M12: 0 | N12: 0 | O12: =SUM(B12:N12) -> 100000
A13: Bank Guarantee Deposit | B13: =Assumptions!B104 -> 25000 | C13: 0 | D13: 0 | E13: 0 | F13: 0 | G13: 0 | H13: 0 | I13: 0 | J13: 0 | K13: 0 | L13: 0 | M13: 0 | N13: 0 | O13: =SUM(B13:N13) -> 0
A14: Company Registration & Legal | B14: =Assumptions!B105 -> 5000 | C14: 0 | D14: 0 | E14: 0 | F14: 0 | G14: 0 | H14: 0 | I14: 0 | J14: 0 | K14: 0 | L14: 0 | M14: 0 | N14: 0 | O14: =SUM(B14:N14) -> 5000
A15: Pre-Launch Marketing | B15: =Assumptions!B106 -> 10000 | C15: 0 | D15: 0 | E15: 0 | F15: 0 | G15: 0 | H15: 0 | I15: 0 | J15: 0 | K15: 0 | L15: 0 | M15: 0 | N15: 0 | O15: =SUM(B15:N15) -> 10000
A17: Cost of Revenue (Variable) | B17: 0 | C17: ='Monthly P&L'!C32 -> 7312.5 | D17: ='Monthly P&L'!D32 -> 4733.3392 | E17: ='Monthly P&L'!E32 -> 5207.5645 | F17: ='Monthly P&L'!F32 -> 5980.0404 | G17: ='Monthly P&L'!G32 -> 6958.6111 | H17: ='Monthly P&L'!H32 -> 8100.1537 | I17: ='Monthly P&L'!I32 -> 9428.337 | J17: ='Monthly P&L'!J32 -> 10979.091 | ... N17: ='Monthly P&L'!N32 -> 20421.956 | O17: =SUM(B17:N17) -> 124351.4
A18: Operating Expenses (Fixed + Semi) | B18: 0 | C18: ='Monthly P&L'!C45 -> 35630.833 | D18: ='Monthly P&L'!D45 -> 27425.527 | E18: ='Monthly P&L'!E45 -> 27695.167 | F18: ='Monthly P&L'!F45 -> 28305.067 | G18: ='Monthly P&L'!G45 -> 29963.267 | H18: ='Monthly P&L'!H45 -> 30992.867 | I18: ='Monthly P&L'!I45 -> 32200.667 | J18: ='Monthly P&L'!J45 -> 33606.467 | ... N18: ='Monthly P&L'!N45 -> 42305.267 | O18: =SUM(B18:N18) -> 400237.13
A19: Total Cash Outflows | B19: =SUM(B11:B18) -> 150000 | C19: =SUM(C11:C18) -> 42943.333 | D19: =SUM(D11:D18) -> 32158.866 | E19: =SUM(E11:E18) -> 32902.731 | F19: =SUM(F11:F18) -> 34285.107 | G19: =SUM(G11:G18) -> 36921.878 | H19: =SUM(H11:H18) -> 39093.02 | I19: =SUM(I11:I18) -> 41629.004 | ... N19: =SUM(N11:N18) -> 62727.223 | O19: =SUM(B19:N19) -> 674588.53
A21: NET CASH FLOW | B21: =B8-B19 -> 40000 | C21: =C8-C19 -> -42943.333 | D21: =D8-D19 -> -30278.866 | E21: =E8-E19 -> -27051.481 | F21: =F8-F19 -> -27133.857 | G21: =G8-G19 -> -28410.628 | H21: =H8-H19 -> -29062.77 | I21: =I8-I19 -> -29856.254 | ... N21: =N8-N19 -> -36059.223 | O21: =SUM(B21:N21) -> -340707.28
A23: Opening Cash Balance | B23: 0 | C23: =B25 -> 40000 | D23: =C25 -> -2943.3333 | E23: =D25 -> -33222.199 | F23: =E25 -> -60273.68 | G23: =F25 -> -87407.537 | H23: =G25 -> -115818.17 | I23: =H25 -> -144880.94 | J23: =I25 -> -174737.19 | ... N23: =M25 -> -304648.06
A24: Net Cash Flow | B24: =B21 -> 40000 | C24: =C21 -> -42943.333 | D24: =D21 -> -30278.866 | E24: =E21 -> -27051.481 | F24: =F21 -> -27133.857 | G24: =G21 -> -28410.628 | H24: =H21 -> -29062.77 | I24: =I21 -> -29856.254 | ... N24: =N21 -> -36059.223
A25: CLOSING CASH BALANCE | B25: =B23+B24 -> 40000 | C25: =C23+C24 -> -2943.3333 | D25: =D23+D24 -> -33222.199 | E25: =E23+E24 -> -60273.68 | F25: =F23+F24 -> -87407.537 | G25: =G23+G24 -> -115818.17 | H25: =H23+H24 -> -144880.94 | I25: =I23+I24 -> -174737.19 | ... N25: =N23+N24 -> -340707.28 | O25: =N25 -> -340707.28
A27: CASH RUNWAY ANALYSIS
A28: Monthly Cash Burn / Generation | B28: =B21 -> 40000 | C28: =C21 -> -42943.333 | D28: =D21 -> -30278.866 | E28: =E21 -> -27051.481 | F28: =F21 -> -27133.857 | G28: =G21 -> -28410.628 | H28: =H21 -> -29062.77 | I28: =I21 -> -29856.254 | ... N28: =N21 -> -36059.223 | O28: =N25 -> -340707.28
A29: Cumulative Cash Burn | B29: =B28 -> 40000 | C29: =B29+C28 -> -2943.3333 | D29: =C29+D28 -> -33222.199 | E29: =D29+E28 -> -60273.68 | F29: =E29+F28 -> -87407.537 | G29: =F29+G28 -> -115818.17 | H29: =G29+H28 -> -144880.94 | I29: =H29+I28 -> -174737.19 | J29: =I29+J28 -> -205465 | ... N29: =M29+N28 -> -340707.28 | O29: =N29 -> -340707.28
A30: Months of Runway Remaining | B30: =IF(B28>=0,"N/A",IF(B25<=0,0,ROUND(-B25/B28,1))) -> N/A | C30: =IF(C28>=0,"N/A",IF(C25<=0,0,ROUND(-C25/C28,1))) -> 0 | D30: =IF(D28>=0,"N/A",IF(D25<=0,0,ROUND(-D25/D28,1))) -> 0 | E30: =IF(E28>=0,"N/A",IF(E25<=0,0,ROUND(-E25/E28,1))) -> 0 | F30: =IF(F28>=0,"N/A",IF(F25<=0,0,ROUND(-F25/F28,1))) -> 0 | G30: =IF(G28>=0,"N/A",IF(G25<=0,0,ROUND(-G25/G28,1))) -> 0 | H30: =IF(H28>=0,"N/A",IF(H25<=0,0,ROUND(-H25/H28,1))) -> 0 | I30: =IF(I28>=0,"N/A",IF(I25<=0,0,ROUND(-I25/I28,1))) -> 0 | ... N30: =IF(N28>=0,"N/A",IF(N25<=0,0,ROUND(-N25/N28,1))) -> 0
A32: KEY CASH METRICS
A33: Metric | B33: Value | D33: Metric | E33: Value
A34: Pre-Launch Capital | B34: =Assumptions!B109 -> 190000 | D34: Year 1 Total Revenue (Cash In) | E34: =O7 -> 143881.25
A35: Year 1 Closing Cash Balance | B35: =N25 -> -340707.28 | D35: Year 1 Total Outflows | E35: =O19 -> 674588.53
A36: Peak Monthly Burn | B36: =MIN(C28:N28) -> -42943.333 | D36: Avg Monthly Burn (M1-M12) | E36: =AVERAGE(C28:N28) -> -31725.607
A38: Additional Funding Required | B38: =IF(N25<0,ABS(N25),0) -> 340707.28 | D38: Recommended Raise (Burn + 30% Buffer) | E38: =ROUND(B38*1.3,-3) -> 443000
A39: Recommended Raise (USD) | B39: =E38*Assumptions!$B$15 -> 624630 | D39: Runway After Raise (months) | E39: =ROUND(E38/ABS(E36),1) -> 14
A42: 5-YEAR CASH FLOW PROJECTION
A43: All figures in Jordanian Dinars (JOD) | Year 1 from Monthly P&L, Years 2-5 from Multi-Year Projections
A45: Line Item | B45: Year 1 | C45: Year 2 | D45: Year 3 | E45: Year 4 | F45: Year 5 | G45: 5-Yr Total
A46: CASH INFLOWS
A47: Seed Capital / Investment | B47: =Assumptions!B109 -> 190000 | C47: 0 | D47: 0 | E47: 0 | F47: 0 | G47: =SUM(B47:F47) -> 190000
A48: Subscription Revenue | B48: ='Multi-Year Projections'!B21 -> 143881.25 | C48: ='Multi-Year Projections'!C21 -> 816763.5 | D48: ='Multi-Year Projections'!D21 -> 1712220.7 | E48: ='Multi-Year Projections'!E21 -> 3034126.5 | F48: ='Multi-Year Projections'!F21 -> 4711707.1 | G48: =SUM(B48:F48) -> 10418699
A49: Ancillary Revenue | B49: ='Multi-Year Projections'!B22 -> 0 | C49: ='Multi-Year Projections'!C22 -> 24120 | D49: ='Multi-Year Projections'!D22 -> 118140 | E49: ='Multi-Year Projections'!E22 -> 358884 | F49: ='Multi-Year Projections'!F22 -> 841680 | G49: =SUM(B49:F49) -> 1342824
A50: Total Cash Inflows | B50: =SUM(B47:B49) -> 333881.25 | C50: =SUM(C47:C49) -> 840883.5 | D50: =SUM(D47:D49) -> 1830360.7 | E50: =SUM(E47:E49) -> 3393010.5 | F50: =SUM(F47:F49) -> 5553387.1 | G50: =SUM(B50:F50) -> 11951523
A52: CASH OUTFLOWS
...

Sheet Stress Tests
A1: WASEL — STRESS TESTS & SENSITIVITY ANALYSIS
A2: Impact analysis on Year 1 financials under adverse scenarios | Updated for 3-tier cohort model
A4: SCENARIO 1: TRANSITION CHURN SENSITIVITY
A5: Metric | B5: Base Case | C5: M0→50% churn | D5: M0→50%, M2+ 10% | E5: All churn 2x | F5: Notes
A6: M0→M1 Churn | B6: 0.25 | C6: 0.5 | D6: 0.5 | E6: 0.6 | F6: First payment wall is #1 risk
A7: M2+ Ongoing Churn | B7: 0.04 | C7: 0.05 | D7: 0.1 | E7: 0.1 | F7: Higher ongoing attrition
A8: Est. EoY Active Drivers | B8: ='Monthly P&L'!N11 -> 1256 | C8: 750 | D8: 500 | E8: 350 | F8: Churn is the #1 risk to the model
A9: Assessment | B9: Planned | C9: Manageable | D9: Concerning | E9: Critical | F9: Low pricing mitigates churn pressure
A11: SCENARIO 2: COMBINED DOWNSIDE STRESS TEST
A12: Stress Factor | B12: Base Case | C12: Downside | D12: Impact
A13: M0→M1 retention | B13: 75% survive | C13: 50% survive | D13: ~30% fewer drivers reach full pricing
A14: M2+ ongoing churn | B14: 4%/mo | C14: 10%/mo | D14: Active driver pool shrinks faster
A15: Mandatory insurance increase | B15: JD 8.65/driver/mo | C15: JD 20/driver/mo | D15: ~JD 120K additional cost/yr at scale
A16: Avg trips per driver per day | B16: 9 trips/day | C16: 5 trips/day | D16: Reduces driver income → may increase churn
A18: Combined Impact | B18: Base Case (Y1) | C18: All-Downside (Y1) | D18: Δ Change
A19: End-of-Year Active Drivers | B19: ='Monthly P&L'!N11 -> 1256 | C19: 350 | D19: =(C19-B19)/B19 -> -0.72133758
A20: Annual Revenue (JOD) | B20: ='Monthly P&L'!O23 -> 143881.25 | C20: 45000 | D20: =(C20-B20)/B20 -> -0.68724208
A21: Annual Net Income (JOD) | B21: ='Monthly P&L'!O53 -> -392373.95 | C21: -500000 | D21: =(C21-B21)/B21 -> 0.2742946
A22: Assessment | B22: Losses expected Y1; funded by seed | C22: CRITICAL: Requires bridge funding
A24: SCENARIO 3: SUBSCRIPTION FEE SENSITIVITY (BLENDED M2+ FEE)
A25: Metric | B25: JD 22/mo | C25: JD 27/mo | D25: JD 32.25 (Base) | E25: JD 38/mo | F25: JD 45/mo | G25: Notes
A26: Blended Monthly Fee (JOD) | B26: 22 | C26: 27 | D26: =Assumptions!B50 -> 32.25 | E26: 38 | F26: 45
A27: Est. Annual Revenue (JOD) | B27: =ROUND(B20*(B26/D26),0) -> 98152 | C27: =ROUND(B20*(C26/D26),0) -> 120459 | D27: =B20 -> 143881.25 | E27: =ROUND(B20*(E26/D26),0) -> 169534 | F27: =ROUND(B20*(F26/D26),0) -> 200765
A28: vs Base Case Revenue | B28: =(B27-D27)/D27 -> -0.31782633 | C28: =(C27-D27)/D27 -> -0.16278876 | D28: BASE | E28: =(E27-D27)/D27 -> 0.17829113 | F28: =(F27-D27)/D27 -> 0.39535207
A29: Fee as % of Driver Gross (~JD 520/mo) | B29: =B26/Assumptions!$B$11 -> 0.03966966 | C29: =C26/Assumptions!$B$11 -> 0.048685492 | D29: =D26/Assumptions!$B$11 -> 0.058152115 | E29: =E26/Assumptions!$B$11 -> 0.068520322 | F29: =F26/Assumptions!$B$11 -> 0.081142486 | G29: vs 30% at Uber/Careem
A31: SCENARIO 4: BREAK-EVEN BY ACTIVE M2+ DRIVER COUNT
A32: Active M2+ Drivers | B32: Monthly Revenue | C32: Monthly COGS | D32: Monthly OPEX | E32: Monthly P&L | F32: Status
A33: 500 | B33: =A33*Assumptions!$B$50 -> 16125 | C33: =A33*Assumptions!$B$59+Assumptions!$B$63+Assumptions!$B$64+Assumptions!$B$65 -> 5725 | D33: =Assumptions!$C$87+Assumptions!$B$69+Assumptions!$C$98+Assumptions!$C$85 -> 21983.333 | E33: =B33-C33-D33 -> -11583.333 | F33: ❌ Loss
A34: 1000 | B34: =A34*Assumptions!$B$50 -> 32250 | C34: =A34*Assumptions!$B$59+Assumptions!$B$63+Assumptions!$B$64+Assumptions!$B$65 -> 10050 | D34: =Assumptions!$C$87+Assumptions!$B$69+Assumptions!$C$98+Assumptions!$C$85 -> 21983.333 | E34: =B34-C34-D34 -> 216.66667 | F34: ❌ Loss
A35: 1500 | B35: =A35*Assumptions!$B$50 -> 48375 | C35: =A35*Assumptions!$B$59+Assumptions!$B$63+Assumptions!$B$64+Assumptions!$B$65 -> 14375 | D35: =Assumptions!$C$87+Assumptions!$B$69+Assumptions!$C$98+Assumptions!$C$85 -> 21983.333 | E35: =B35-C35-D35 -> 12016.667 | F35: =IF(E35>=0,"✅ Profitable","❌ Loss") -> ✅ Profitable
A36: 2000 | B36: =A36*Assumptions!$B$50 -> 64500 | C36: =A36*Assumptions!$B$59+Assumptions!$B$63+Assumptions!$B$64+Assumptions!$B$65 -> 18700 | D36: =Assumptions!$C$87+Assumptions!$B$69+Assumptions!$C$98+Assumptions!$C$85 -> 21983.333 | E36: =B36-C36-D36 -> 23816.667 | F36: =IF(E36>=0,"✅ Profitable","❌ Loss") -> ✅ Profitable
A37: 3000 | B37: =A37*Assumptions!$B$50 -> 96750 | C37: =A37*Assumptions!$B$59+Assumptions!$B$63+Assumptions!$B$64+Assumptions!$B$65 -> 27350 | D37: =Assumptions!$C$87+Assumptions!$B$69+Assumptions!$C$98+Assumptions!$C$85 -> 21983.333 | E37: =B37-C37-D37 -> 47416.667 | F37: =IF(E37>=0,"✅ Profitable","❌ Loss") -> ✅ Profitable
A38: 5000 | B38: =A38*Assumptions!$B$50 -> 161250 | C38: =A38*Assumptions!$B$59+Assumptions!$B$63+Assumptions!$B$64+Assumptions!$B$65 -> 44650 | D38: =Assumptions!$C$87+Assumptions!$B$69+Assumptions!$C$98+Assumptions!$C$85 -> 21983.333 | E38: =B38-C38-D38 -> 94616.667 | F38: =IF(E38>=0,"✅ Profitable","❌ Loss") -> ✅ Profitable
A40: Break-even requires ~1,200 active M2+ drivers paying full tier pricing (excl. M0/M1 onboarding drivers)
A42: SCENARIO 5: UNIT ECONOMICS SENSITIVITY (INVESTOR STRESS TEST)
A43: What happens to LTV/CAC when churn assumptions worsen?
A44: Mature Churn Rate (M6+) | B44: Avg Lifespan (Mo) | C44: LTV (JOD) | D44: LTV/CAC | E44: Survives? | F44: Assessment
A45: 0.025 | B45: 27 | C45: =B45*'Unit Economics'!$B$44 -> 476.85712 | D45: =C45/'Unit Economics'!$B$53 -> 10.596825 | E45: ✅ Yes — LTV/CAC >3x | F45: ✅ Base case — strong
A46: 0.05 | B46: 16 | C46: =B46*'Unit Economics'!$B$44 -> 282.582 | D46: =C46/'Unit Economics'!$B$53 -> 6.2796 | E46: ✅ Yes — LTV/CAC >3x | F46: ✅ Still healthy (>3x)
A47: 0.075 | B47: 11 | C47: =B47*'Unit Economics'!$B$44 -> 194.27513 | D47: =C47/'Unit Economics'!$B$53 -> 4.317225 | E47: ✅ Yes — LTV/CAC >3x | F47: ✅ Acceptable
...

Sheet Multi-Year Projections
A1: WASEL — 5-YEAR FINANCIAL PROJECTIONS
A2: All figures in Jordanian Dinars (JOD) | USD equivalent at 1 JOD = $1.41 | Cohort model
A4: Line Item | B4: Year 1 | C4: Year 2 | D4: Year 3 | E4: Year 4 | F4: Year 5 | G4: 5-Yr CAGR | H4: 5-Yr Total
A5: GROWTH ASSUMPTIONS
A6: Annual Net Driver Growth Rate | B6: N/A | C6: 1.2 | D6: 0.85 | E6: 0.6 | F6: 0.45
A7: Blended Fee Growth (Tier Mix Shift) | B7: N/A | C7: 0.05 | D7: 0.07 | E7: 0.05 | F7: 0.03
A8: Fixed OPEX Growth Rate | B8: N/A | C8: 0.3 | D8: 0.2 | E8: 0.15 | F8: 0.1
A9: Cities Operating | B9: 1 | C9: 3 | D9: 4 | E9: 6 | F9: 8
A10: Ancillary Revenue / Driver / Mo (JOD) | B10: 0 | C10: 1 | D10: 2.5 | E10: 4.5 | F10: 7
A13: KEY OPERATING METRICS
A14: Active Drivers (End of Year) | B14: ='Monthly P&L'!N11 -> 1256 | C14: =ROUND(B14*(1+C6),0) -> 2763 | D14: =ROUND(C14*(1+D6),0) -> 5112 | E14: =ROUND(D14*(1+E6),0) -> 8179 | F14: =ROUND(E14*(1+F6),0) -> 11860 | G14: =(F14/B14)^(1/4)-1 -> 0.75296709
A15: Avg Active Drivers (Annual) | B15: ='Monthly P&L'!O6/2 -> 958 | C15: =ROUND((B14+C14)/2,0) -> 2010 | D15: =ROUND((C14+D14)/2,0) -> 3938 | E15: =ROUND((D14+E14)/2,0) -> 6646 | F15: =ROUND((E14+F14)/2,0) -> 10020
A16: Blended Monthly Fee / Driver (JOD) | B16: =Assumptions!B50 -> 32.25 | C16: =B16*(1+C7) -> 33.8625 | D16: =C16*(1+D7) -> 36.232875 | E16: =D16*(1+E7) -> 38.044519 | F16: =E16*(1+F7) -> 39.185854
A17: Team Headcount | B17: 5 | C17: 9 | D17: 15 | E17: 22 | F17: 30
A20: REVENUE
A21: Subscription Revenue | B21: ='Monthly P&L'!O23 -> 143881.25 | C21: =C15*C16*12 -> 816763.5 | D21: =D15*D16*12 -> 1712220.7 | E21: =E15*E16*12 -> 3034126.5 | F21: =F15*F16*12 -> 4711707.1 | H21: =SUM(B21:F21) -> 10418699
A22: Ancillary Revenue (Ads, Data, Partnerships) | B22: 0 | C22: =C15*C10*12 -> 24120 | D22: =D15*D10*12 -> 118140 | E22: =E15*E10*12 -> 358884 | F22: =F15*F10*12 -> 841680 | H22: =SUM(B22:F22) -> 1342824
A23: TOTAL REVENUE | B23: =B21+B22 -> 143881.25 | C23: =C21+C22 -> 840883.5 | D23: =D21+D22 -> 1830360.7 | E23: =E21+E22 -> 3393010.5 | F23: =F21+F22 -> 5553387.1 | G23: =(F23/B23)^(1/4)-1 -> 1.4925188 | H23: =SUM(B23:F23) -> 11761523
A24: YoY Revenue Growth | B24: N/A | C24: =(C23-B23)/B23 -> 4.8442883 | D24: =(D23-C23)/C23 -> 1.1767114 | E24: =(E23-D23)/D23 -> 0.85373866 | F24: =(F23-E23)/E23 -> 0.63671382
A27: COST OF REVENUE
A28: Payment Processing Fees | B28: ='Monthly P&L'!O26 -> 1510.7531 | C28: =C23*Assumptions!$B$13*Assumptions!$B$14 -> 8829.2768 | D28: =D23*Assumptions!$B$13*Assumptions!$B$14 -> 19218.788 | E28: =E23*Assumptions!$B$13*Assumptions!$B$14 -> 35626.61 | F28: =F23*Assumptions!$B$13*Assumptions!$B$14 -> 58310.565 | H28: =SUM(B28:F28) -> 123495.99
A29: Insurance Program Costs | B29: ='Monthly P&L'!O27 -> 62409.75 | C29: =C15*Assumptions!$B$59*12 -> 208638 | D29: =D15*Assumptions!$B$59*12 -> 408764.4 | E29: =E15*Assumptions!$B$59*12 -> 689854.8 | F29: =F15*Assumptions!$B$59*12 -> 1040076 | H29: =SUM(B29:F29) -> 2409743
A30: Cloud & Tech Infrastructure | B30: ='Monthly P&L'!O28+'Monthly P&L'!O29+'Monthly P&L'!O30 -> 31690.9 | C30: =ROUND(B30*(C15/B15)^0.6,0) -> 49435 | D30: =ROUND(C30*(D15/C15)^0.6,0) -> 74009 | E30: =ROUND(D30*(E15/D15)^0.6,0) -> 101311 | F30: =ROUND(E30*(F15/E15)^0.6,0) -> 129611 | H30: =SUM(B30:F30) -> 386056.9
A31: Driver Onboarding & Verification | B31: ='Monthly P&L'!O31 -> 28740 | C31: =ROUND((C14-B14+C14*0.15)*Assumptions!$B$67,0) -> 28822 | D31: =ROUND((D14-C14+D14*0.12)*Assumptions!$B$67,0) -> 44437 | E31: =ROUND((E14-D14+E14*0.1)*Assumptions!$B$67,0) -> 58274 | F31: =ROUND((F14-E14+F14*0.08)*Assumptions!$B$67,0) -> 69447 | H31: =SUM(B31:F31) -> 229720
A32: Total Cost of Revenue | B32: =SUM(B28:B31) -> 124351.4 | C32: =SUM(C28:C31) -> 295724.28 | D32: =SUM(D28:D31) -> 546429.19 | E32: =SUM(E28:E31) -> 885066.41 | F32: =SUM(F28:F31) -> 1297444.6 | H32: =SUM(B32:F32) -> 3149015.8
