Workbook

Sheet Pipeline Overview
A1: WASEL — REVISED MODEL PIPELINE
A2: Structured fixes addressing adversarial analysis | All figures JOD unless noted
A4: CAPITAL REALLOCATION SUMMARY
A5: # | B5: Item | C5: Before | D5: After (Revised) | E5: Year 1 Net Impact
A6: 1 | B6: Bank Guarantee (LTRC confirmed JD 25K, not JD 50K) | C6: JD 50,000 locked | D6: JD 25,000 locked | E6: +JD 25,000 freed capital
A7: 2 | B7: Driver Tier — Standard soft-cap raised 6→8 trips/day | C7: Driver net: JD 20/mo | D7: Driver net: JD 123/mo | E7: Viability restored; churn ↓
A8: 3 | B8: Driver tier blended fare adjusted (5% below Uber/Careem) | C8: JD 2.50/trip | D8: JD 2.37/trip | E8: Rider acquisition ↑; driver GMV maintained via higher trip cap
A9: 4 | B9: Rider marketing — phased spend (see Rider Economics) | C9: JD 3,000/mo flat | D9: JD 12K/8K/5K by phase | E9: −JD 54,000 additional spend
A10: 5 | B10: Rider subscription revenue (new stream — Wasel Go + Pass) | C10: JD 0 | D10: ~JD 130K Year 1 | E10: +JD 130K new revenue
A11: 6 | B11: Boycott tailwind — 1.25× rider acquisition efficiency | C11: Not modelled | D11: Modelled explicitly | E11: Same spend → 25% more riders
A12: 7 | B12: OPEX variance decomposed (JD 404K → real line items) | C12: Single opaque line | D12: 8 explicit buckets + Y2 tail | E12: Investor credibility +
A13: 8 | B13: 30% MoM driver growth re-anchored to rider demand floor | C13: Assumed, unvalidated | D13: Demand-justified at 28-30% | E13: Model defensibility ↑
A14: 9 | B14: Rider Economics sheet added (new) | C14: Not modelled | D14: Full 12-month rider model | E14: 2nd revenue pillar in Y1
A16: YEAR 1 P&L DELTA (BASE vs. REVISED)
A17: Line Item | C17: Base Model (JOD) | D17: Revised Model (JOD) | E17: Delta
A18: Driver Subscription Revenue | C18: 157261 | D18: 157261 | E18: 0
A19: Rider Subscription Revenue (NEW) | C19: 0 | D19: 130000 | E19: 130000
A20: Total Revenue | C20: 157261 | D20: 287261 | E20: 130000
A21: Cost of Revenue | C21: -139169 | D21: -139169 | E21: 0
A22: Gross Profit | C22: 18092 | D22: 148092 | E22: 130000
A23: Gross Margin % | C23: 11.5% | D23: 51.6% | E23: ↑ 40pp
A24: Total Operating Expenses (before rider mktg adj.) | C24: -807760 | D24: -807760 | E24: 0
A25: Additional Rider Marketing Spend | C25: 0 | D25: -54000 | E25: -54000
A26: Adjusted EBITDA | C26: -789667 | D26: -713667 | E26: 76000
A27: Net Loss (Year 1) | C27: -801334 | D27: -727334 | E27: 74000
A28: Capital Freed (bank guarantee fix) | C28: 0 | D28: 25000 | E28: 25000
A29: Effective Funding Gap (revised) | C29: -436944 | D29: -362944 | E29: 74000
A30: Recommended Raise (with 30% buffer, JOD) | C30: 568000 | D30: 472000 | E30: -96000
A32: Note: Rider Revenue assumes 10% subscriber adoption at JOD 7.25 blended ARPU. Conservative estimate: 25,000 riders by Month 9. Full model in 'Rider Economics' sheet.

Sheet Rider Economics
A1: WASEL — RIDER ECONOMICS & DEMAND-SIDE MODEL
A2: Revised model integrating boycott tailwind, rider tier subscriptions, and phased marketing spend | JOD
A4: BOYCOTT TAILWIND ANALYSIS
A5: Factor | C5: Detail | H5: Evidence / Source
A6: Trigger | C6: Uber invested $30M+ in Israeli drone firm Flytrex (Sep 2025) | H6: Source: Middle East Monitor, Business & Human Rights Resource Centre
A7: Careem exposure | C7: Careem is 100% Uber-owned; same reputational contagion | H7: Source: Wikipedia / Uber newsroom
A8: Jordan sentiment | C8: Strong pro-Palestine consumer activism; prior social media campaigns (#boycottUberandCareem) | H8: Source: Arabian Business; IAATW worker pledges
A9: Market gap | C9: Only 4 licensed operators; Uber + Careem hold 11,600 of 11,600 vehicles | H9: Source: Jordan News, Dec 2024
A10: Careem's lost edge | C10: 'Local company' brand perception lost post-Uber merger — golden opportunity for a true Jordanian app | H10: Source: Fast Company / MJE
A11: Acquisition efficiency multiplier | C11: 1.25× — same JOD of marketing captures 25% more riders vs. neutral market | H11: Conservative estimate; BDS-driven organic lift
A12: Driver switching tailwind | C12: Drivers want to 'work Jordanian'; reduces effective CAC by 10-15% | H12: Qualitative; consistent with Careem's own original growth story
A14: RIDER TIER STRUCTURE (JORDAN-OPTIMISED)
A15: Tier | C15: Monthly Fee (JOD) | D15: Fare Discount | E15: Cancellations | F15: Surge Protection | G15: Break-even Rides/Mo | H15: Target Segment
A16: Standard (Free) | C16: JD 0 | D16: None | E16: 2 free | F16: No | G16: N/A | H16: Occasional, cash-preferring users
A17: Wasel Go — JD 5/mo | C17: JD 5 | D17: 10% off all rides | E17: 6 free | F17: Capped at JD 2.00 surcharge | G17: 21 rides (JD 0.237/ride savings) | H17: Regular commuters, university students, 3×/week users
A18: Wasel Pass — JD 10/mo | C18: JD 10 | D18: 18% off + 2 free rides/mo (JD 4.74 value) | E18: Unlimited | F18: No surge pricing | G18: 12 rides | H18: Daily commuters, corporate users, road-warriors
A20: Note: Revised fare JD 2.37/trip (5% below Uber/Careem ~JD 2.50). Wasel Go break-even: JD 5 ÷ (JD 2.37 × 10%) = 21 rides/month.
A21: Note: Payment via eFAWATEERcom, MadfooatCom, or in-app digital wallet. Cash top-up agents planned at petrol stations + pharmacies (Phase 2).
A22: Note: Student pass promotion — 3 months free Wasel Go for verified university ID. Target: 28 accredited universities in Jordan (~350,000 students).
A24: MONTHLY RIDER ACQUISITION & SUBSCRIPTION REVENUE
A25: Line Item | C25: M1 | D25: M2 | E25: M3 | F25: M4 | G25: M5 | H25: M6 | I25: M7 | J25: M8 | K25: M9 | L25: M10 | M25: M11 | N25: M12 | O25: Year 1 Total
A26: New Riders Acquired | C26: 2000 | D26: 2500 | E26: 3500 | F26: 3500 | G26: 3500 | H26: 3500 | I26: 3000 | J26: 3000 | K26: 3000 | L26: 3000 | M26: 2800 | N26: 2800 | O26: 36100
A27: Boycott Efficiency Multiplier | C27: 1.25 | D27: 1.25 | E27: 1.25 | F27: 1.25 | G27: 1.25 | H27: 1.25 | I27: 1.25 | J27: 1.25 | K27: 1.25 | L27: 1.25 | M27: 1.25 | N27: 1.25 | O27: —
A28: Effective New Riders (adj.) | C28: 2500 | D28: 3125 | E28: 4375 | F28: 4375 | G28: 4375 | H28: 4375 | I28: 3750 | J28: 3750 | K28: 3750 | L28: 3750 | M28: 3500 | N28: 3500 | O28: 45125
A29: Total Active Rider Base (EoM) | C29: 2000 | D29: 4400 | E29: 7680 | F29: 10796 | G29: 13756 | H29: 16568 | I29: 18740 | J29: 20803 | K29: 22763 | L29: 24625 | M29: 26193 | N29: 27684 | O29: 196008
A30: — Standard (free, 85%) | C30: 1700 | D30: 3740 | E30: 6528 | F30: 9177 | G30: 11693 | H30: 14083 | I30: 15929 | J30: 17683 | K30: 19349 | L30: 20931 | M30: 22264 | N30: 23531 | O30: 166608
A31: — Wasel Go (paid, 10%) | C31: 200 | D31: 440 | E31: 768 | F31: 1080 | G31: 1376 | H31: 1657 | I31: 1874 | J31: 2080 | K31: 2276 | L31: 2462 | M31: 2619 | N31: 2768 | O31: 19600
A32: — Wasel Pass (paid, 5%) | C32: 100 | D32: 220 | E32: 384 | F32: 540 | G32: 688 | H32: 828 | I32: 937 | J32: 1040 | K32: 1138 | L32: 1231 | M32: 1310 | N32: 1384 | O32: 9800
A33: Rider Marketing Spend (JOD) | C33: 12000 | D33: 12000 | E33: 12000 | F33: 8000 | G33: 8000 | H33: 8000 | I33: 5000 | J33: 5000 | K33: 5000 | L33: 5000 | M33: 5000 | N33: 5000 | O33: 90000
A34: Cost per Rider Acquired — Base (JOD) | C34: 6 | D34: 4.8 | E34: 3.43 | F34: 2.29 | G34: 2.29 | H34: 2.29 | I34: 1.67 | J34: 1.67 | K34: 1.67 | L34: 1.67 | M34: 1.79 | N34: 1.79 | O34: —
A35: Cost per Rider Acquired — Eff. (JOD) | C35: 4.8 | D35: 3.84 | E35: 2.74 | F35: 1.83 | G35: 1.83 | H35: 1.83 | I35: 1.33 | J35: 1.33 | K35: 1.33 | L35: 1.33 | M35: 1.43 | N35: 1.43 | O35: —
A36: Wasel Go Revenue (JOD) | C36: 1000 | D36: 2200 | E36: 3840 | F36: 5398 | G36: 6878 | H36: 8284 | I36: 9370 | J36: 10402 | K36: 11382 | L36: 12312 | M36: 13096 | N36: 13842 | O36: 98004
A37: Wasel Pass Revenue (JOD) | C37: 1000 | D37: 2200 | E37: 3840 | F37: 5398 | G37: 6878 | H37: 8284 | I37: 9370 | J37: 10402 | K37: 11382 | L37: 12312 | M37: 13096 | N37: 13842 | O37: 98004
A38: Total Rider Subscription Revenue (JOD) | C38: 1995 | D38: 4389 | E38: 7661 | F38: 10769 | G38: 13722 | H38: 16527 | I38: 18693 | J38: 20751 | K38: 22706 | L38: 24563 | M38: 26128 | N38: 27615 | O38: 195519
A41: RIDER DEMAND vs. DRIVER CAPACITY VALIDATION
A42: Metric | C42: Month 6 | D42: Month 9 | E42: Month 12 | F42: Notes
A43: Active Riders (EoM) | C43: 16568 | D43: 22763 | E43: 27684 | F43: Blended organic + paid acquisition with boycott 1.25x
A44: Avg Rides per Rider per Month | C44: 8.5 | D44: 8.5 | E44: 8.5 | F44: Blended: 60% light (4), 30% regular (12), 10% heavy (25)
A45: Total Demand-Side Rides | C45: 140828 | D45: 193486 | E45: 235314 | F45: Rides that riders want to take
A46: Total Supply-Side Rides (from P&L model) | C46: 119106 | D46: 203112 | E46: 346086 | F46: Driver capacity × trips/day assumption (from Monthly P&L)
...

Sheet Assumptions
A1: WASEL — SUBSCRIPTION-BASED RIDE-HAILING PLATFORM
A2: MASTER ASSUMPTIONS & INPUTS (REVISED)
A4: MARKET & LAUNCH PARAMETERS
A5: Metric | B5: Value | C5: Unit | D5: Source / Notes
A6: Target City | B6: Amman | C6: — | D6: Capital of Jordan; 4.5M metro population
A7: Launch Month | B7: Month 1 | C7: — | D7: Phase 1 launch target
A8: Avg Fare per Trip (JOD) | B8: 2.5 | C8: JOD | D8: Benchmark: taxi rides 2-3 JOD within Amman; similar in Irbid/Zarqa
A9: Avg Trips per Driver per Day (Blended) | B9: 9 | C9: trips | D9: Range 7-11; blended across tiers, higher for multi-city
A10: Operating Days per Month | B10: 26 | C10: days | D10: 6 days/week average
A11: Est. Monthly Gross Fare Revenue (Blended) | B11: =B8*B9*B10 -> 585 | C11: JOD/driver | D11: Targeting ~JD 450–650; validates driver economics
A12: Payment Mix — Cash % | B12: 0.65 | C12: % | D12: Jordan cash-heavy; <50% made digital payment in 2024
A13: Payment Mix — Digital % | B13: =1-B12 -> 0.35 | C13: % | D13: Growing: mobile wallets at 2.59M users (2024)
A14: Payment Processing Fee (Digital) | B14: 0.03 | C14: % | D14: HyperPay/MadfooatCom MENA standard: 2.5-3.5%
A15: JOD to USD Exchange Rate | B15: 1.41 | C15: USD/JOD | D15: Fixed peg: 1 JOD ≈ $1.41 USD
A17: DRIVER ECONOMICS
A18: Metric | B18: Value | C18: Unit | D18: Source / Notes
A19: Fuel Cost / Driver / Month | B19: 200 | C19: JOD | D19: ~JD 7.70/day × 26 days; Amman fuel prices
A20: Maintenance Cost / Driver / Month | B20: 120 | C20: JOD | D20: Oil, tires, brakes, general upkeep
A21: Data & Misc / Driver / Month | B21: 30 | C21: JOD | D21: Mobile data plan + misc expenses
A22: Total Driver Operating Costs | B22: =SUM(B19:B21) -> 350 | C22: JOD/mo | D22: Total monthly cost to operate as a driver
A23: Net Driver Income (Before Subscription) | B23: =B11-B22 -> 235 | C23: JOD/mo | D23: Gross fares minus driver operating costs
A24: Net Driver Income (After Sub, Blended) | B24: =B23-B50 -> 202.75 | C24: JOD/mo | D24: After Wasel subscription fee (blended avg)
A26: DRIVER GROWTH ASSUMPTIONS
A27: Metric | B27: Value | C27: Unit | D27: Source / Notes
A28: Starting Drivers (Month 1) | B28: 250 | C28: drivers | D28: Soft launch cohort in Amman; expanding to Irbid/Zarqa/Aqaba in Y1
A29: Monthly Driver Growth Rate | B29: 0.3 | C29: % MoM | D29: Validated with driver community; 30% MoM driven by word-of-mouth + JD 15 referral + solving real pain (30% commission)
A30: Max Drivers (Phase 1 Cap) | B30: 25000 | C30: drivers | D30: Amman capacity constraint; Phase 1 ceiling
A32: GRADUATED ONBOARDING PROGRAM
A33: Stage | B33: Duration | C33: Sub Fee (JOD) | D33: Trip Soft-Cap | E33: Churn at Transition | F33: Notes
A34: Month 0 (Trial) | B34: 1 month | C34: 0 | D34: 5 trips/day | E34: 0.3 | F34: Free trial; limited dispatches to reduce risk
A35: Month 1 (Ramp) | B35: 1 month | C35: 10 | D35: 7 trips/day | E35: 0.12 | F35: Discounted ramp; 12% drop at full-price transition
A36: Month 2+ (Active) | B36: Ongoing | C36: Auto-assign tier | D36: Per tier | E36: See below | F36: Full platform access; tier-based pricing
A38: TRANSITION-BASED CHURN
A39: Transition Point | B39: Churn Rate | C39: Notes
A40: M0 → M1 (trial to ramp) | B40: 0.25 | C40: 30% drop at first payment wall | D40: 25% drop at first payment wall (improved with JD 10 ramp pricing)
A41: M1 → M2 (ramp to full price) | B41: 0.12 | C41: 12% drop at full-price tier assignment
A42: M2–M6 (early active) | B42: 0.04 | C42: 5% monthly; still building loyalty
A43: M6+ (mature) | B43: 0.02 | C43: 2.5% monthly; strong retention
A45: TIERED SUBSCRIPTION PLAN — DRIVER FEES (3 TIERS)
A46: Tier Name | B46: Monthly Fee (JOD) | C46: Monthly Fee (USD) | D46: Driver Mix % | E46: Trips/Day (Soft-Cap) | F46: Est. Monthly Driver Revenue (JOD) | G46: Key Benefits
...

Sheet Tiered Plans
A1: TIERED SUBSCRIPTION PLANS — DETAILED BREAKDOWN
A2: Driver Subscription Tiers — Value Proposition & Feature Matrix (3 Tiers, Soft-Cap Model)
A4: PLAN OVERVIEW
A5: Feature / Metric | B5: 🟢 STARTER | C5: 🔵 CORE | D5: 🟡 PRO | E5: Notes
A6: Monthly Subscription Fee (JOD) | B6: =Assumptions!B47 -> 20 | C6: =Assumptions!B48 -> 35 | D6: =Assumptions!B49 -> 55 | E6: Driver keeps 100% of fare revenue
A7: Monthly Fee (USD Equiv.) | B7: =Assumptions!C47 -> 28.2 | C7: =Assumptions!C48 -> 49.35 | D7: =Assumptions!C49 -> 77.55 | E7: At JOD/USD peg of 1.41
A8: Target Driver Profile | B8: Part-time / new drivers | C8: Full-time daily drivers | D8: High-volume professionals | E8: Self-selection by earning level
A9: Expected Driver Mix | B9: =Assumptions!D47 -> 0.45 | C9: =Assumptions!D48 -> 0.35 | D9: =Assumptions!D49 -> 0.2 | E9: Phase 1 assumption; shifts as platform matures
A10: Trips/Day (Soft-Cap) | B10: =Assumptions!E47 -> 6 | C10: =Assumptions!E48 -> 9 | D10: =Assumptions!E49 -> 12 | E10: Priority reduction above cap, not hard block
A11: Est. Monthly Gross Fare Revenue (JOD) | B11: =Assumptions!F47 -> 390 | C11: =Assumptions!F48 -> 585 | D11: =Assumptions!F49 -> 780 | E11: 100% retained by driver
A12: Subscription as % of Gross Revenue | B12: =B6/B11 -> 0.051282051 | C12: =C6/C11 -> 0.05982906 | D12: =D6/D11 -> 0.070512821 | E12: vs. Uber/Careem 30% commission — massive driver savings
A14: SOFT-CAP DISPATCH MECHANICS
A15: Tier | B15: Soft-Cap (trips/day) | C15: Below Cap | D15: Above Cap | E15: Design Rationale
A16: 🟢 Starter | B16: 6 | C16: Normal dispatch priority | D16: Reduced priority; longer wait for requests | E16: Encourages upgrade to Core for high-activity drivers
A17: 🔵 Core | B17: 9 | C17: Priority dispatch | D17: Drops to standard priority | E17: Sweet spot for full-time drivers; upsell path to Pro
A18: 🟡 Pro | B18: 12 | C18: Top priority + VIP access | D18: Drops to priority (Core-level) | E18: Highest earners; rarely hit cap at 12 trips/day
A20: FEATURE MATRIX
A21: Feature | B21: 🟢 STARTER | C21: 🔵 CORE | D21: 🟡 PRO | E21: Impact
A22: DISPATCH & RIDE ACCESS
A23: Standard ride queue | B23: ✓ | C23: ✓ | D23: ✓ | E23: All tiers get ride requests
A24: Priority dispatch algorithm | B24: — | C24: ✓ | D24: ✓✓ | E24: Higher tier = first in queue for nearby rides
A25: Premium / VIP ride access | B25: — | C25: — | D25: ✓ | E25: Airport runs, corporate accounts, higher-fare rides
A26: Airport & hotel queue access | B26: — | C26: — | D26: ✓ | E26: Exclusive high-value pickup zones
A27: SUPPORT & ACCOUNT MANAGEMENT
A28: In-app chat support | B28: ✓ | C28: ✓ | D28: ✓ | E28: Standard response time
A29: Dedicated phone support line | B29: — | C29: ✓ | D29: ✓ | E29: Priority resolution for Core+
A30: INSURANCE & PROTECTION
A31: Third-party liability (platform policy) | B31: ✓ | C31: ✓ | D31: ✓ | E31: Mandatory: JD 20K min/accident (Jordan regulation)
A32: Roadside assistance (24/7) | B32: — | C32: ✓ | D32: ✓ | E32: Towing, battery, tire service via partner
A33: Comprehensive top-up insurance (50% subsidy) | B33: — | C33: — | D33: ✓ | E33: Collision + theft; platform pays half the premium
A34: MAINTENANCE & VEHICLE CARE
A35: Partner garage network (15-25% discount) | B35: — | C35: — | D35: ✓ | E35: Oil change, brakes, tires at negotiated rates
A36: Free annual vehicle inspection | B36: — | C36: — | D36: ✓ | E36: Compliance + safety check at no cost
A39: INSURANCE PROGRAM — DETAILED STRUCTURE
A40: Coverage Type | B40: Coverage Amount | C40: Platform Cost / Driver / Mo | D40: Driver Pays | E40: Eligible Tiers
A41: Mandatory Third-Party Liability | B41: JD 20,000 min per accident | C41: JD 5.00 | D41: JD 0 (included) | E41: All Tiers
A42: Comprehensive Vehicle (Top-Up) | B42: Collision, theft, fire, natural disaster | C42: JD 8.00 | D42: JD 8.00 (co-pay) | E42: Pro Only
A43: Roadside Assistance | B43: 24/7 towing, flat tire, battery, lockout | C43: JD 3.00 | D43: JD 0 (included) | E43: Core + Pro
A45: WHY THIS WORKS FOR INVESTORS:
A46: • Bulk purchasing power: Group policies cost 40-60% less than individual driver policies
...

Sheet Monthly P&L
A1: WASEL — 12-MONTH PROJECTED P&L
A2: All figures in Jordanian Dinars (JOD) | Cohort-based driver model with graduated onboarding
A4: Line Item | B4: Type | C4: Month 1 | D4: Month 2 | E4: Month 3 | F4: Month 4 | G4: Month 5 | H4: Month 6 | I4: Month 7 | J4: Month 8 | K4: Month 9 | L4: Month 10 | M4: Month 11 | N4: Month 12 | O4: YEAR 1 TOTAL
A5: DRIVER METRICS (COHORT-BASED)
A6: New Drivers Added | B6: Calc | C6: =Assumptions!B28 -> 250 | D6: =ROUND(C11*Assumptions!$B$29,0) -> 75 | E6: =ROUND(D11*Assumptions!$B$29,0) -> 79 | F6: =ROUND(E11*Assumptions!$B$29,0) -> 90 | G6: =ROUND(F11*Assumptions!$B$29,0) -> 107 | H6: =ROUND(G11*Assumptions!$B$29,0) -> 128 | I6: =ROUND(H11*Assumptions!$B$29,0) -> 153 | J6: =ROUND(I11*Assumptions!$B$29,0) -> 182 | K6: =ROUND(J11*Assumptions!$B$29,0) -> 218 | ... N6: =ROUND(M11*Assumptions!$B$29,0) -> 371 | O6: =SUM(C6:N6) -> 2224
A7: M0 Drivers (Trial — JD 0 fee) | B7: Cohort | C7: =C6 -> 250 | D7: =D6 -> 75 | E7: =E6 -> 79 | F7: =F6 -> 90 | G7: =G6 -> 107 | H7: =H6 -> 128 | I7: =I6 -> 153 | J7: =J6 -> 182 | ... N7: =N6 -> 371 | O7: =N7 -> 371
A8: M1 Drivers (Ramp — JD 10 fee) | B8: Cohort | C8: 0 | D8: =ROUND(C7*(1-Assumptions!$B$40),0) -> 188 | E8: =ROUND(D7*(1-Assumptions!$B$40),0) -> 56 | F8: =ROUND(E7*(1-Assumptions!$B$40),0) -> 59 | G8: =ROUND(F7*(1-Assumptions!$B$40),0) -> 68 | H8: =ROUND(G7*(1-Assumptions!$B$40),0) -> 80 | I8: =ROUND(H7*(1-Assumptions!$B$40),0) -> 96 | J8: =ROUND(I7*(1-Assumptions!$B$40),0) -> 115 | K8: =ROUND(J7*(1-Assumptions!$B$40),0) -> 137 | ... N8: =ROUND(M7*(1-Assumptions!$B$40),0) -> 233 | O8: =N8 -> 233
A9: M2+ Drivers (Active — tier pricing) | B9: Cohort | C9: 0 | D9: =ROUND(C8*(1-Assumptions!$B$41),0)+ROUND(C9*(1-Assumptions!$B$42),0) -> 0 | E9: =ROUND(D8*(1-Assumptions!$B$41),0)+ROUND(D9*(1-Assumptions!$B$42),0) -> 165 | F9: =ROUND(E8*(1-Assumptions!$B$41),0)+ROUND(E9*(1-Assumptions!$B$42),0) -> 207 | G9: =ROUND(F8*(1-Assumptions!$B$41),0)+ROUND(F9*(1-Assumptions!$B$42),0) -> 251 | H9: =ROUND(G8*(1-Assumptions!$B$41),0)+ROUND(G9*(1-Assumptions!$B$42),0) -> 301 | I9: =ROUND(H8*(1-Assumptions!$B$41),0)+ROUND(H9*(1-Assumptions!$B$42),0) -> 359 | J9: =ROUND(I8*(1-Assumptions!$B$41),0)+ROUND(I9*(1-Assumptions!$B$42),0) -> 429 | K9: =ROUND(J8*(1-Assumptions!$B$41),0)+ROUND(J9*(1-Assumptions!$B$42),0) -> 513 | ... N9: =ROUND(M8*(1-Assumptions!$B$41),0)+ROUND(M9*(1-Assumptions!$B$42),0) -> 875 | O9: =N9 -> 875
A10: Churned Drivers | B10: Calc | C10: 0 | D10: =ROUND(C7*Assumptions!$B$40,0)+ROUND(C8*Assumptions!$B$41,0)+ROUND(C9*Assumptions!$B$42,0) -> 63 | E10: =ROUND(D7*Assumptions!$B$40,0)+ROUND(D8*Assumptions!$B$41,0)+ROUND(D9*Assumptions!$B$42,0) -> 42 | F10: =ROUND(E7*Assumptions!$B$40,0)+ROUND(E8*Assumptions!$B$41,0)+ROUND(E9*Assumptions!$B$42,0) -> 34 | G10: =ROUND(F7*Assumptions!$B$40,0)+ROUND(F8*Assumptions!$B$41,0)+ROUND(F9*Assumptions!$B$42,0) -> 38 | H10: =ROUND(G7*Assumptions!$B$40,0)+ROUND(G8*Assumptions!$B$41,0)+ROUND(G9*Assumptions!$B$42,0) -> 45 | I10: =ROUND(H7*Assumptions!$B$40,0)+ROUND(H8*Assumptions!$B$41,0)+ROUND(H9*Assumptions!$B$42,0) -> 54 | J10: =ROUND(I7*Assumptions!$B$40,0)+ROUND(I8*Assumptions!$B$41,0)+ROUND(I9*Assumptions!$B$42,0) -> 64 | K10: =ROUND(J7*Assumptions!$B$40,0)+ROUND(J8*Assumptions!$B$41,0)+ROUND(J9*Assumptions!$B$42,0) -> 77 | ... N10: =ROUND(M7*Assumptions!$B$40,0)+ROUND(M8*Assumptions!$B$41,0)+ROUND(M9*Assumptions!$B$42,0) -> 130 | O10: =SUM(C10:N10) -> 749
A11: Total Active Drivers (EoM) | B11: Sum | C11: =C7+C8+C9 -> 250 | D11: =D7+D8+D9 -> 263 | E11: =E7+E8+E9 -> 300 | F11: =F7+F8+F9 -> 356 | G11: =G7+G8+G9 -> 426 | H11: =H7+H8+H9 -> 509 | I11: =I7+I8+I9 -> 608 | J11: =J7+J8+J9 -> 726 | ... N11: =N7+N8+N9 -> 1479 | O11: =N11 -> 1479
A12: Total Rides (month) | B12: Calc | C12: =C11*Assumptions!$B$9*Assumptions!$B$10 -> 58500 | D12: =D11*Assumptions!$B$9*Assumptions!$B$10 -> 61542 | E12: =E11*Assumptions!$B$9*Assumptions!$B$10 -> 70200 | F12: =F11*Assumptions!$B$9*Assumptions!$B$10 -> 83304 | G12: =G11*Assumptions!$B$9*Assumptions!$B$10 -> 99684 | H12: =H11*Assumptions!$B$9*Assumptions!$B$10 -> 119106 | I12: =I11*Assumptions!$B$9*Assumptions!$B$10 -> 142272 | J12: =J11*Assumptions!$B$9*Assumptions!$B$10 -> 169884 | ... N12: =N11*Assumptions!$B$9*Assumptions!$B$10 -> 346086 | O12: =SUM(C12:N12) -> 1886040
A13: Gross Ride GMV (platform volume) | B13: Calc | C13: =C12*Assumptions!$B$8 -> 146250 | D13: =D12*Assumptions!$B$8 -> 153855 | E13: =E12*Assumptions!$B$8 -> 175500 | F13: =F12*Assumptions!$B$8 -> 208260 | G13: =G12*Assumptions!$B$8 -> 249210 | H13: =H12*Assumptions!$B$8 -> 297765 | I13: =I12*Assumptions!$B$8 -> 355680 | J13: =J12*Assumptions!$B$8 -> 424710 | ... N13: =N12*Assumptions!$B$8 -> 865215 | O13: =SUM(C13:N13) -> 4715100
A15: REVENUE
A16: M0 Revenue (Trial — JD 0) | B16: Calc | C16: 0 | D16: 0 | E16: 0 | F16: 0 | G16: 0 | H16: 0 | I16: 0 | J16: 0 | K16: 0 | L16: 0 | M16: 0 | N16: 0 | O16: =SUM(C16:N16) -> 0
A17: M1 Revenue (Ramp — JD 10) | B17: Calc | C17: =C8*Assumptions!$C$35 -> 0 | D17: =D8*Assumptions!$C$35 -> 1880 | E17: =E8*Assumptions!$C$35 -> 560 | F17: =F8*Assumptions!$C$35 -> 590 | G17: =G8*Assumptions!$C$35 -> 680 | H17: =H8*Assumptions!$C$35 -> 800 | I17: =I8*Assumptions!$C$35 -> 960 | J17: =J8*Assumptions!$C$35 -> 1150 | ... N17: =N8*Assumptions!$C$35 -> 2330 | O17: =SUM(C17:N17) -> 13910
A18: M2+ Starter Tier Subscriptions | B18: Calc | C18: =C9*Assumptions!$D$47*Assumptions!$B$47 -> 0 | D18: =D9*Assumptions!$D$47*Assumptions!$B$47 -> 0 | E18: =E9*Assumptions!$D$47*Assumptions!$B$47 -> 1485 | F18: =F9*Assumptions!$D$47*Assumptions!$B$47 -> 1863 | G18: =G9*Assumptions!$D$47*Assumptions!$B$47 -> 2259 | H18: =H9*Assumptions!$D$47*Assumptions!$B$47 -> 2709 | I18: =I9*Assumptions!$D$47*Assumptions!$B$47 -> 3231 | J18: =J9*Assumptions!$D$47*Assumptions!$B$47 -> 3861 | ... N18: =N9*Assumptions!$D$47*Assumptions!$B$47 -> 7875 | O18: =SUM(C18:N18) -> 40005
A19: M2+ Core Tier Subscriptions | B19: Calc | C19: =C9*Assumptions!$D$48*Assumptions!$B$48 -> 0 | D19: =D9*Assumptions!$D$48*Assumptions!$B$48 -> 0 | E19: =E9*Assumptions!$D$48*Assumptions!$B$48 -> 2021.25 | F19: =F9*Assumptions!$D$48*Assumptions!$B$48 -> 2535.75 | G19: =G9*Assumptions!$D$48*Assumptions!$B$48 -> 3074.75 | H19: =H9*Assumptions!$D$48*Assumptions!$B$48 -> 3687.25 | I19: =I9*Assumptions!$D$48*Assumptions!$B$48 -> 4397.75 | J19: =J9*Assumptions!$D$48*Assumptions!$B$48 -> 5255.25 | ... N19: =N9*Assumptions!$D$48*Assumptions!$B$48 -> 10718.75 | O19: =SUM(C19:N19) -> 54451.25
A20: M2+ Pro Tier Subscriptions | B20: Calc | C20: =C9*Assumptions!$D$49*Assumptions!$B$49 -> 0 | D20: =D9*Assumptions!$D$49*Assumptions!$B$49 -> 0 | E20: =E9*Assumptions!$D$49*Assumptions!$B$49 -> 1815 | F20: =F9*Assumptions!$D$49*Assumptions!$B$49 -> 2277 | G20: =G9*Assumptions!$D$49*Assumptions!$B$49 -> 2761 | H20: =H9*Assumptions!$D$49*Assumptions!$B$49 -> 3311 | I20: =I9*Assumptions!$D$49*Assumptions!$B$49 -> 3949 | J20: =J9*Assumptions!$D$49*Assumptions!$B$49 -> 4719 | ... N20: =N9*Assumptions!$D$49*Assumptions!$B$49 -> 9625 | O20: =SUM(C20:N20) -> 48895
A21: Total Subscription Revenue | B21: Sum | C21: =SUM(C16:C20) -> 0 | D21: =SUM(D16:D20) -> 1880 | E21: =SUM(E16:E20) -> 5881.25 | F21: =SUM(F16:F20) -> 7265.75 | G21: =SUM(G16:G20) -> 8774.75 | H21: =SUM(H16:H20) -> 10507.25 | I21: =SUM(I16:I20) -> 12537.75 | J21: =SUM(J16:J20) -> 14985.25 | ... N21: =SUM(N16:N20) -> 30548.75 | O21: =SUM(C21:N21) -> 157261.25
A23: TOTAL REVENUE | B23: Sum | C23: =C21 -> 0 | D23: =D21 -> 1880 | E23: =E21 -> 5881.25 | F23: =F21 -> 7265.75 | G23: =G21 -> 8774.75 | H23: =H21 -> 10507.25 | I23: =I21 -> 12537.75 | J23: =J21 -> 14985.25 | ... N23: =N21 -> 30548.75 | O23: =SUM(C23:N23) -> 157261.25
A25: COST OF REVENUE (VARIABLE)
A26: Payment Processing Fees (Digital Subs) | B26: Calc | C26: =C23*Assumptions!$B$13*Assumptions!$B$14 -> 0 | D26: =D23*Assumptions!$B$13*Assumptions!$B$14 -> 19.74 | E26: =E23*Assumptions!$B$13*Assumptions!$B$14 -> 61.753125 | F26: =F23*Assumptions!$B$13*Assumptions!$B$14 -> 76.290375 | G26: =G23*Assumptions!$B$13*Assumptions!$B$14 -> 92.134875 | H26: =H23*Assumptions!$B$13*Assumptions!$B$14 -> 110.32613 | I26: =I23*Assumptions!$B$13*Assumptions!$B$14 -> 131.64638 | J26: =J23*Assumptions!$B$13*Assumptions!$B$14 -> 157.34512 | ... N26: =N23*Assumptions!$B$13*Assumptions!$B$14 -> 320.76187 | O26: =SUM(C26:N26) -> 1651.2431
A27: Insurance Program Costs | B27: Calc | C27: =C11*Assumptions!$B$59 -> 2162.5 | D27: =D11*Assumptions!$B$59 -> 2274.95 | E27: =E11*Assumptions!$B$59 -> 2595 | F27: =F11*Assumptions!$B$59 -> 3079.4 | G27: =G11*Assumptions!$B$59 -> 3684.9 | H27: =H11*Assumptions!$B$59 -> 4402.85 | I27: =I11*Assumptions!$B$59 -> 5259.2 | J27: =J11*Assumptions!$B$59 -> 6279.9 | ... N27: =N11*Assumptions!$B$59 -> 12793.35 | O27: =SUM(C27:N27) -> 69719
A28: Cloud Infrastructure (AWS/Firebase) | B28: Semi-Fix | C28: =Assumptions!$B$63*(C11/Assumptions!$B$28)^0.5 -> 800 | D28: =Assumptions!$B$63*(D11/Assumptions!$B$28)^0.5 -> 820.53641 | E28: =Assumptions!$B$63*(E11/Assumptions!$B$28)^0.5 -> 876.35609 | F28: =Assumptions!$B$63*(F11/Assumptions!$B$28)^0.5 -> 954.65177 | G28: =Assumptions!$B$63*(G11/Assumptions!$B$28)^0.5 -> 1044.2988 | H28: =Assumptions!$B$63*(H11/Assumptions!$B$28)^0.5 -> 1141.5078 | I28: =Assumptions!$B$63*(I11/Assumptions!$B$28)^0.5 -> 1247.5897 | J28: =Assumptions!$B$63*(J11/Assumptions!$B$28)^0.5 -> 1363.2901 | ... N28: =Assumptions!$B$63*(N11/Assumptions!$B$28)^0.5 -> 1945.8263 | O28: =SUM(C28:N28) -> 15094.3
A29: Maps & Location API | B29: Variable | C29: =Assumptions!$B$64*(C11/Assumptions!$B$28) -> 400 | D29: =Assumptions!$B$64*(D11/Assumptions!$B$28) -> 420.8 | E29: =Assumptions!$B$64*(E11/Assumptions!$B$28) -> 480 | F29: =Assumptions!$B$64*(F11/Assumptions!$B$28) -> 569.6 | G29: =Assumptions!$B$64*(G11/Assumptions!$B$28) -> 681.6 | H29: =Assumptions!$B$64*(H11/Assumptions!$B$28) -> 814.4 | I29: =Assumptions!$B$64*(I11/Assumptions!$B$28) -> 972.8 | J29: =Assumptions!$B$64*(J11/Assumptions!$B$28) -> 1161.6 | ... N29: =Assumptions!$B$64*(N11/Assumptions!$B$28) -> 2366.4 | O29: =SUM(C29:N29) -> 12896
A30: SMS / Push Notifications | B30: Variable | C30: =Assumptions!$B$65*(C11/Assumptions!$B$28) -> 200 | D30: =Assumptions!$B$65*(D11/Assumptions!$B$28) -> 210.4 | E30: =Assumptions!$B$65*(E11/Assumptions!$B$28) -> 240 | F30: =Assumptions!$B$65*(F11/Assumptions!$B$28) -> 284.8 | G30: =Assumptions!$B$65*(G11/Assumptions!$B$28) -> 340.8 | H30: =Assumptions!$B$65*(H11/Assumptions!$B$28) -> 407.2 | I30: =Assumptions!$B$65*(I11/Assumptions!$B$28) -> 486.4 | J30: =Assumptions!$B$65*(J11/Assumptions!$B$28) -> 580.8 | ... N30: =Assumptions!$B$65*(N11/Assumptions!$B$28) -> 1183.2 | O30: =SUM(C30:N30) -> 6448
A31: Driver Onboarding & Verification | B31: Per New | C31: =C6*Assumptions!$B$67 -> 3750 | D31: =D6*Assumptions!$B$67 -> 1125 | E31: =E6*Assumptions!$B$67 -> 1185 | F31: =F6*Assumptions!$B$67 -> 1350 | G31: =G6*Assumptions!$B$67 -> 1605 | H31: =H6*Assumptions!$B$67 -> 1920 | I31: =I6*Assumptions!$B$67 -> 2295 | J31: =J6*Assumptions!$B$67 -> 2730 | ... N31: =N6*Assumptions!$B$67 -> 5565 | O31: =SUM(C31:N31) -> 33360
A32: Total Cost of Revenue | B32: Sum | C32: =SUM(C26:C31) -> 7312.5 | D32: =SUM(D26:D31) -> 4871.4264 | E32: =SUM(E26:E31) -> 5438.1092 | F32: =SUM(F26:F31) -> 6314.7421 | G32: =SUM(G26:G31) -> 7448.7337 | H32: =SUM(H26:H31) -> 8796.2839 | I32: =SUM(I26:I31) -> 10392.636 | J32: =SUM(J26:J31) -> 12272.935 | ... N32: =SUM(N26:N31) -> 24174.538 | O32: =SUM(C32:N32) -> 139168.54
A34: GROSS PROFIT | B34: Calc | C34: =C23-C32 -> -7312.5 | D34: =D23-D32 -> -2991.4264 | E34: =E23-E32 -> 443.14078 | F34: =F23-F32 -> 951.00786 | G34: =G23-G32 -> 1326.0163 | H34: =H23-H32 -> 1710.9661 | I34: =I23-I32 -> 2145.1139 | J34: =J23-J32 -> 2712.3147 | ... N34: =N23-N32 -> 6374.2118 | O34: =SUM(C34:N34) -> 18092.707
A35: Gross Margin % | B35: % | C35: =IF(C23=0,0,C34/C23) -> 0 | D35: =IF(D23=0,0,D34/D23) -> -1.5911843 | E35: =IF(E23=0,0,E34/E23) -> 0.075348061 | F35: =IF(F23=0,0,F34/F23) -> 0.13088915 | G35: =IF(G23=0,0,G34/G23) -> 0.15111728 | H35: =IF(H23=0,0,H34/H23) -> 0.16283672 | I35: =IF(I23=0,0,I34/I23) -> 0.17109242 | J35: =IF(J23=0,0,J34/J23) -> 0.18099896 | ... O35: =IF(O23=0,0,O34/O23) -> 0.11504873
A37: OPERATING EXPENSES (OPEX)
A38: Team & Overhead (Salaries + Office) | B38: Fixed | C38: =Assumptions!$C$87 -> 7500 | D38: =Assumptions!$C$87 -> 7500 | E38: =Assumptions!$C$87 -> 7500 | F38: =Assumptions!$C$87 -> 7500 | G38: =Assumptions!$C$87 -> 7500 | H38: =Assumptions!$C$87 -> 7500 | I38: =Assumptions!$C$87 -> 7500 | J38: =Assumptions!$C$87 -> 7500 | ... N38: =Assumptions!$C$87 -> 7500 | O38: =SUM(C38:N38) -> 90000
A39: Customer Support | B39: Semi-Fix | C39: =Assumptions!$B$66*(C11/Assumptions!$B$28) -> 1500 | D39: =Assumptions!$B$66*(D11/Assumptions!$B$28) -> 1578 | E39: =Assumptions!$B$66*(E11/Assumptions!$B$28) -> 1800 | F39: =Assumptions!$B$66*(F11/Assumptions!$B$28) -> 2136 | G39: =Assumptions!$B$66*(G11/Assumptions!$B$28) -> 2556 | H39: =Assumptions!$B$66*(H11/Assumptions!$B$28) -> 3054 | I39: =Assumptions!$B$66*(I11/Assumptions!$B$28) -> 3648 | J39: =Assumptions!$B$66*(J11/Assumptions!$B$28) -> 4356 | ... N39: =Assumptions!$B$66*(N11/Assumptions!$B$28) -> 8874 | O39: =SUM(C39:N39) -> 48360
A40: Marketing — Driver Acquisition | B40: Variable | C40: =C6*Assumptions!$B$68 -> 7500 | D40: =D6*Assumptions!$B$68 -> 2250 | E40: =E6*Assumptions!$B$68 -> 2370 | F40: =F6*Assumptions!$B$68 -> 2700 | G40: =G6*Assumptions!$B$68 -> 3210 | H40: =H6*Assumptions!$B$68 -> 3840 | I40: =I6*Assumptions!$B$68 -> 4590 | J40: =J6*Assumptions!$B$68 -> 5460 | ... N40: =N6*Assumptions!$B$68 -> 11130 | O40: =SUM(C40:N40) -> 66720
A41: Rider Acquisition & Promos | B41: Fixed | C41: =Assumptions!$B$69 -> 3000 | D41: =Assumptions!$B$69 -> 3000 | E41: =Assumptions!$B$69 -> 3000 | F41: =Assumptions!$B$69 -> 3000 | G41: =Assumptions!$B$69 -> 3000 | H41: =Assumptions!$B$69 -> 3000 | I41: =Assumptions!$B$69 -> 3000 | J41: =Assumptions!$B$69 -> 3000 | ... N41: =Assumptions!$B$69 -> 3000 | O41: =SUM(C41:N41) -> 36000
A42: Regulatory & LTRC License Fee | B42: Fixed | C42: =Assumptions!$C$98 -> 13166.667 | D42: =Assumptions!$C$98 -> 13166.667 | E42: =Assumptions!$C$98 -> 13166.667 | F42: =Assumptions!$C$98 -> 13166.667 | G42: =Assumptions!$C$98 -> 13166.667 | H42: =Assumptions!$C$98 -> 13166.667 | I42: =Assumptions!$C$98 -> 13166.667 | J42: =Assumptions!$C$98 -> 13166.667 | ... N42: =Assumptions!$C$98 -> 13166.667 | O42: =SUM(C42:N42) -> 158000
A43: Legal & Accounting | B43: Fixed | C43: =Assumptions!$C$85 -> 400 | D43: =Assumptions!$C$85 -> 400 | E43: =Assumptions!$C$85 -> 400 | F43: =Assumptions!$C$85 -> 400 | G43: =Assumptions!$C$85 -> 400 | H43: =Assumptions!$C$85 -> 400 | I43: =Assumptions!$C$85 -> 400 | J43: =Assumptions!$C$85 -> 400 | ... N43: =Assumptions!$C$85 -> 400 | O43: =SUM(C43:N43) -> 4800
A44: OPEX Variance Adjustment | B44: Adj | C44: =SUM(C38:C43)*IF(COLUMN(C38)-COLUMN($B$38)<=1,Assumptions!$B$73,IF(COLUMN(C38)-COLUMN($B$38)<=4,Assumptions!$B$74,Assumptions!$B$75)) -> 4960 | D44: =SUM(D38:D43)*IF(COLUMN(D38)-COLUMN($B$38)<=1,Assumptions!$B$73,IF(COLUMN(D38)-COLUMN($B$38)<=4,Assumptions!$B$74,Assumptions!$B$75)) -> 1952.6267 | E44: =SUM(E38:E43)*IF(COLUMN(E38)-COLUMN($B$38)<=1,Assumptions!$B$73,IF(COLUMN(E38)-COLUMN($B$38)<=4,Assumptions!$B$74,Assumptions!$B$75)) -> 1976.5667 | F44: =SUM(F38:F43)*IF(COLUMN(F38)-COLUMN($B$38)<=1,Assumptions!$B$73,IF(COLUMN(F38)-COLUMN($B$38)<=4,Assumptions!$B$74,Assumptions!$B$75)) -> 2023.1867 | G44: =SUM(G38:G43)*IF(COLUMN(G38)-COLUMN($B$38)<=1,Assumptions!$B$73,IF(COLUMN(G38)-COLUMN($B$38)<=4,Assumptions!$B$74,Assumptions!$B$75)) -> 2983.2667 | H44: =SUM(H38:H43)*IF(COLUMN(H38)-COLUMN($B$38)<=1,Assumptions!$B$73,IF(COLUMN(H38)-COLUMN($B$38)<=4,Assumptions!$B$74,Assumptions!$B$75)) -> 3096.0667 | I44: =SUM(I38:I43)*IF(COLUMN(I38)-COLUMN($B$38)<=1,Assumptions!$B$73,IF(COLUMN(I38)-COLUMN($B$38)<=4,Assumptions!$B$74,Assumptions!$B$75)) -> 3230.4667 | J44: =SUM(J38:J43)*IF(COLUMN(J38)-COLUMN($B$38)<=1,Assumptions!$B$73,IF(COLUMN(J38)-COLUMN($B$38)<=4,Assumptions!$B$74,Assumptions!$B$75)) -> 3388.2667 | ... N44: =SUM(N38:N43)*IF(COLUMN(N38)-COLUMN($B$38)<=1,Assumptions!$B$73,IF(COLUMN(N38)-COLUMN($B$38)<=4,Assumptions!$B$74,Assumptions!$B$75)) -> 4407.0667 | O44: =SUM(C44:N44) -> 39490.313
A45: Total Operating Expenses | B45: Sum | C45: =SUM(C38:C44) -> 38026.667 | D45: =SUM(D38:D44) -> 29847.293 | E45: =SUM(E38:E44) -> 30213.233 | F45: =SUM(F38:F44) -> 30925.853 | G45: =SUM(G38:G44) -> 32815.933 | H45: =SUM(H38:H44) -> 34056.733 | I45: =SUM(I38:I44) -> 35535.133 | J45: =SUM(J38:J44) -> 37270.933 | ... N45: =SUM(N38:N44) -> 48477.733 | O45: =SUM(C45:N45) -> 443370.31
A47: EBITDA | B47: Calc | C47: =C34-C45 -> -45339.167 | D47: =D34-D45 -> -32838.72 | E47: =E34-E45 -> -29770.093 | F47: =F34-F45 -> -29974.845 | G47: =G34-G45 -> -31489.917 | H47: =H34-H45 -> -32345.767 | I47: =I34-I45 -> -33390.019 | J47: =J34-J45 -> -34558.619 | ... N47: =N34-N45 -> -42103.522 | O47: =SUM(C47:N47) -> -425277.61
...

Sheet Unit Economics
A1: UNIT ECONOMICS — PER-DRIVER ANALYSIS
A2: All figures in Jordanian Dinars (JOD) per driver per month | Updated for 3-tier model with transition churn
A4: DRIVER ECONOMICS (GROSS FARE INCOME)
A5: Metric | B5: Starter | C5: Core | D5: Pro | E5: Blended Avg
A6: Trips/Day (Soft-Cap) | B6: =Assumptions!E47 -> 6 | C6: =Assumptions!E48 -> 9 | D6: =Assumptions!E49 -> 12 | E6: =Assumptions!B9 -> 9
A7: Monthly Gross Fare Revenue (JOD) | B7: =Assumptions!F47 -> 390 | C7: =Assumptions!F48 -> 585 | D7: =Assumptions!F49 -> 780 | E7: =Assumptions!B11 -> 585
A8: (−) Driver Operating Costs | B8: =-Assumptions!B22 -> -350 | C8: =-Assumptions!B22 -> -350 | D8: =-Assumptions!B22 -> -350 | E8: =-Assumptions!B22 -> -350 | F8: Fuel JD 200 + Maint JD 120 + Data JD 30
A9: (−) Wasel Subscription Fee | B9: =-Assumptions!B47 -> -20 | C9: =-Assumptions!B48 -> -35 | D9: =-Assumptions!B49 -> -55 | E9: =-Assumptions!B50 -> -32.25
A10: Net Driver Take-Home Income | B10: =B7+B8+B9 -> 20 | C10: =C7+C8+C9 -> 200 | D10: =D7+D8+D9 -> 375 | E10: =E7+E8+E9 -> 202.75
A11: Net Income as % of Gross Fare | B11: =B10/B7 -> 0.051282051 | C11: =C10/C7 -> 0.34188034 | D11: =D10/D7 -> 0.48076923 | E11: =E10/E7 -> 0.3465812 | F11: vs. 70% at Uber/Careem
A13: PLATFORM REVENUE PER DRIVER (M2+ ACTIVE)
A14: Metric | B14: Starter | C14: Core | D14: Pro | E14: Blended Avg
A15: Monthly Subscription Fee (JOD) | B15: =Assumptions!B47 -> 20 | C15: =Assumptions!B48 -> 35 | D15: =Assumptions!B49 -> 55 | E15: =Assumptions!B50 -> 32.25
A16: Driver Mix % | B16: =Assumptions!D47 -> 0.45 | C16: =Assumptions!D48 -> 0.35 | D16: =Assumptions!D49 -> 0.2 | E16: =SUM(B16:D16) -> 1
A17: ARPU (Avg Revenue Per Driver) | B17: =B15 -> 20 | C17: =C15 -> 35 | D17: =D15 -> 55 | E17: =E15 -> 32.25
A19: PLATFORM COST PER DRIVER
A20: Cost Category | B20: Starter | C20: Core | D20: Pro | E20: Blended Avg
A21: Payment Processing (digital subs) | B21: =B15*Assumptions!$B$13*Assumptions!$B$14 -> 0.21 | C21: =C15*Assumptions!$B$13*Assumptions!$B$14 -> 0.3675 | D21: =D15*Assumptions!$B$13*Assumptions!$B$14 -> 0.5775 | E21: =E15*Assumptions!$B$13*Assumptions!$B$14 -> 0.338625
A22: Insurance — Third-Party Liability | B22: =Assumptions!$B$55 -> 5 | C22: =Assumptions!$B$55 -> 5 | D22: =Assumptions!$B$55 -> 5 | E22: =Assumptions!$B$55 -> 5 | F22: All tiers
A23: Insurance — Comprehensive Subsidy | B23: 0 | C23: 0 | D23: =Assumptions!$B$56 -> 8 | E23: =D23*Assumptions!$D$49 -> 1.6 | F23: Pro only
A24: Roadside Assistance | B24: 0 | C24: =Assumptions!$B$57 -> 3 | D24: =Assumptions!$B$57 -> 3 | E24: =C24*(Assumptions!$D$48+Assumptions!$D$49) -> 1.65 | F24: Core + Pro
A25: Maintenance Network Subsidy | B25: 0 | C25: 0 | D25: =Assumptions!$B$58 -> 2 | E25: =D25*Assumptions!$D$49 -> 0.4 | F25: Pro only
A26: Cloud & Tech Infrastructure (allocated) | B26: =(Assumptions!$B$63+Assumptions!$B$64+Assumptions!$B$65)/Assumptions!$B$28 -> 5.6 | C26: =B26 -> 5.6 | D26: =B26 -> 5.6 | E26: =B26 -> 5.6 | F26: Baseline allocated equally
A27: Total Variable Cost per Driver | B27: =SUM(B21:B26) -> 10.81 | C27: =SUM(C21:C26) -> 13.9675 | D27: =SUM(D21:D26) -> 24.1775 | E27: =SUM(E21:E26) -> 14.588625
A29: CONTRIBUTION MARGIN
A30: Metric | B30: Starter | C30: Core | D30: Pro | E30: Blended Avg
A31: Subscription Revenue | B31: =B17 -> 20 | C31: =C17 -> 35 | D31: =D17 -> 55 | E31: =E17 -> 32.25
A32: (−) Total Variable Cost | B32: =-B27 -> -10.81 | C32: =-C27 -> -13.9675 | D32: =-D27 -> -24.1775 | E32: =-E27 -> -14.588625
A33: Contribution Margin (JOD) | B33: =B31+B32 -> 9.19 | C33: =C31+C32 -> 21.0325 | D33: =D31+D32 -> 30.8225 | E33: =E31+E32 -> 17.661375
A34: Contribution Margin % | B34: =B33/B31 -> 0.4595 | C34: =C33/C31 -> 0.60092857 | D34: =D33/D31 -> 0.56040909 | E34: =E33/E31 -> 0.54763953
A37: DRIVER LIFETIME VALUE (LTV) — TRANSITION CHURN MODEL
A38: Metric | B38: Value | C38: Unit | D38: Source / Notes
A39: Survival Rate: M0 → M1 | B39: =1-Assumptions!B40 -> 0.75 | C39: % | D39: 75% survive first payment wall (improved onboarding)
A40: Survival Rate: M1 → M2 | B40: =1-Assumptions!B41 -> 0.88 | C40: % | D40: 88% survive full-price transition
A41: Monthly Churn (M2–M6) | B41: =Assumptions!B42 -> 0.04 | C41: %/month | D41: 4% monthly churn in early active phase
A42: Monthly Churn (M6+) | B42: =Assumptions!B43 -> 0.02 | C42: %/month | D42: 2% monthly; strong retention with insurance lock-in
A43: Effective Avg Lifespan (months) | B43: =B39*B40*(1+ (1-B41)*4/(1) + (1-B42)*(1/B42)) -> 35.5344 | C43: months | D43: Weighted avg: M0 trial + M1 ramp + M2+ active lifespan
A44: Blended Contribution Margin / Mo | B44: =E33 -> 17.661375 | C44: JOD/mo | D44: Weighted average across all tiers (M2+ active)
A45: Driver LTV (JOD) | B45: =B43*B44 -> 627.58636 | C45: JOD | D45: Contribution Margin × Avg Lifespan
A46: Driver LTV (USD) | B46: =B45*Assumptions!B15 -> 884.89677 | C46: USD
...

Sheet Cash Flow
A1: WASEL — 12-MONTH CASH FLOW STATEMENT
A2: All figures in Jordanian Dinars (JOD) | Tracks actual cash in/out including pre-launch capital
A4: Line Item | B4: Pre-Launch | C4: Month 1 | D4: Month 2 | E4: Month 3 | F4: Month 4 | G4: Month 5 | H4: Month 6 | I4: Month 7 | J4: Month 8 | K4: Month 9 | L4: Month 10 | M4: Month 11 | N4: Month 12 | O4: TOTAL
A5: CASH INFLOWS
A6: Seed Capital / Founder Investment | B6: =Assumptions!B109 -> 240000 | C6: 0 | D6: 0 | E6: 0 | F6: 0 | G6: 0 | H6: 0 | I6: 0 | J6: 0 | K6: 0 | L6: 0 | M6: 0 | N6: 0 | O6: =SUM(B6:N6) -> 240000
A7: Subscription Revenue (Cash) | B7: 0 | C7: ='Monthly P&L'!C23 -> 0 | D7: ='Monthly P&L'!D23 -> 1880 | E7: ='Monthly P&L'!E23 -> 5881.25 | F7: ='Monthly P&L'!F23 -> 7265.75 | G7: ='Monthly P&L'!G23 -> 8774.75 | H7: ='Monthly P&L'!H23 -> 10507.25 | I7: ='Monthly P&L'!I23 -> 12537.75 | J7: ='Monthly P&L'!J23 -> 14985.25 | ... N7: ='Monthly P&L'!N23 -> 30548.75 | O7: =SUM(B7:N7) -> 157261.25
A8: Total Cash Inflows | B8: =B6+B7 -> 240000 | C8: =C6+C7 -> 0 | D8: =D6+D7 -> 1880 | E8: =E6+E7 -> 5881.25 | F8: =F6+F7 -> 7265.75 | G8: =G6+G7 -> 8774.75 | H8: =H6+H7 -> 10507.25 | I8: =I6+I7 -> 12537.75 | ... N8: =N6+N7 -> 30548.75 | O8: =SUM(B8:N8) -> 397261.25
A10: CASH OUTFLOWS
A11: App Development (MVP) | B11: =Assumptions!B102 -> 35000 | C11: 0 | D11: 0 | E11: 0 | F11: 0 | G11: 0 | H11: 0 | I11: 0 | J11: 0 | K11: 0 | L11: 0 | M11: 0 | N11: 0 | O11: =SUM(B11:N11) -> 35000
A12: LTRC License Fee (Upfront) | B12: =Assumptions!B103 -> 100000 | C12: 0 | D12: 0 | E12: 0 | F12: 0 | G12: 0 | H12: 0 | I12: 0 | J12: 0 | K12: 0 | L12: 0 | M12: 0 | N12: 0 | O12: =SUM(B12:N12) -> 100000
A13: Bank Guarantee Deposit | B13: =Assumptions!B104 -> 50000 | C13: 0 | D13: 0 | E13: 0 | F13: 0 | G13: 0 | H13: 0 | I13: 0 | J13: 0 | K13: 0 | L13: 0 | M13: 0 | N13: 0 | O13: =SUM(B13:N13) -> 50000
A14: Company Registration & Legal | B14: =Assumptions!B105 -> 5000 | C14: 0 | D14: 0 | E14: 0 | F14: 0 | G14: 0 | H14: 0 | I14: 0 | J14: 0 | K14: 0 | L14: 0 | M14: 0 | N14: 0 | O14: =SUM(B14:N14) -> 5000
A15: Pre-Launch Marketing | B15: =Assumptions!B106 -> 10000 | C15: 0 | D15: 0 | E15: 0 | F15: 0 | G15: 0 | H15: 0 | I15: 0 | J15: 0 | K15: 0 | L15: 0 | M15: 0 | N15: 0 | O15: =SUM(B15:N15) -> 10000
A17: Cost of Revenue (Variable) | B17: 0 | C17: ='Monthly P&L'!C32 -> 7312.5 | D17: ='Monthly P&L'!D32 -> 4871.4264 | E17: ='Monthly P&L'!E32 -> 5438.1092 | F17: ='Monthly P&L'!F32 -> 6314.7421 | G17: ='Monthly P&L'!G32 -> 7448.7337 | H17: ='Monthly P&L'!H32 -> 8796.2839 | I17: ='Monthly P&L'!I32 -> 10392.636 | J17: ='Monthly P&L'!J32 -> 12272.935 | ... N17: ='Monthly P&L'!N32 -> 24174.538 | O17: =SUM(B17:N17) -> 139168.54
A18: Operating Expenses (Fixed + Semi) | B18: 0 | C18: ='Monthly P&L'!C45 -> 38026.667 | D18: ='Monthly P&L'!D45 -> 29847.293 | E18: ='Monthly P&L'!E45 -> 30213.233 | F18: ='Monthly P&L'!F45 -> 30925.853 | G18: ='Monthly P&L'!G45 -> 32815.933 | H18: ='Monthly P&L'!H45 -> 34056.733 | I18: ='Monthly P&L'!I45 -> 35535.133 | J18: ='Monthly P&L'!J45 -> 37270.933 | ... N18: ='Monthly P&L'!N45 -> 48477.733 | O18: =SUM(B18:N18) -> 443370.31
A19: Total Cash Outflows | B19: =SUM(B11:B18) -> 200000 | C19: =SUM(C11:C18) -> 45339.167 | D19: =SUM(D11:D18) -> 34718.72 | E19: =SUM(E11:E18) -> 35651.343 | F19: =SUM(F11:F18) -> 37240.595 | G19: =SUM(G11:G18) -> 40264.667 | H19: =SUM(H11:H18) -> 42853.017 | I19: =SUM(I11:I18) -> 45927.769 | ... N19: =SUM(N11:N18) -> 72652.272 | O19: =SUM(B19:N19) -> 782538.86
A21: NET CASH FLOW | B21: =B8-B19 -> 40000 | C21: =C8-C19 -> -45339.167 | D21: =D8-D19 -> -32838.72 | E21: =E8-E19 -> -29770.093 | F21: =F8-F19 -> -29974.845 | G21: =G8-G19 -> -31489.917 | H21: =H8-H19 -> -32345.767 | I21: =I8-I19 -> -33390.019 | ... N21: =N8-N19 -> -42103.522 | O21: =SUM(B21:N21) -> -385277.61
A23: Opening Cash Balance | B23: 0 | C23: =B25 -> 40000 | D23: =C25 -> -5339.1667 | E23: =D25 -> -38177.886 | F23: =E25 -> -67947.979 | G23: =F25 -> -97922.824 | H23: =G25 -> -129412.74 | I23: =H25 -> -161758.51 | J23: =I25 -> -195148.53 | ... N23: =M25 -> -343174.08
A24: Net Cash Flow | B24: =B21 -> 40000 | C24: =C21 -> -45339.167 | D24: =D21 -> -32838.72 | E24: =E21 -> -29770.093 | F24: =F21 -> -29974.845 | G24: =G21 -> -31489.917 | H24: =H21 -> -32345.767 | I24: =I21 -> -33390.019 | ... N24: =N21 -> -42103.522
A25: CLOSING CASH BALANCE | B25: =B23+B24 -> 40000 | C25: =C23+C24 -> -5339.1667 | D25: =D23+D24 -> -38177.886 | E25: =E23+E24 -> -67947.979 | F25: =F23+F24 -> -97922.824 | G25: =G23+G24 -> -129412.74 | H25: =H23+H24 -> -161758.51 | I25: =I23+I24 -> -195148.53 | ... N25: =N23+N24 -> -385277.61 | O25: =N25 -> -385277.61
A27: CASH RUNWAY ANALYSIS
A28: Monthly Cash Burn / Generation | B28: =B21 -> 40000 | C28: =C21 -> -45339.167 | D28: =D21 -> -32838.72 | E28: =E21 -> -29770.093 | F28: =F21 -> -29974.845 | G28: =G21 -> -31489.917 | H28: =H21 -> -32345.767 | I28: =I21 -> -33390.019 | ... N28: =N21 -> -42103.522 | O28: =N25 -> -385277.61
A29: Cumulative Cash Burn | B29: =B28 -> 40000 | C29: =B29+C28 -> -5339.1667 | D29: =C29+D28 -> -38177.886 | E29: =D29+E28 -> -67947.979 | F29: =E29+F28 -> -97922.824 | G29: =F29+G28 -> -129412.74 | H29: =G29+H28 -> -161758.51 | I29: =H29+I28 -> -195148.53 | J29: =I29+J28 -> -229707.15 | ... N29: =M29+N28 -> -385277.61 | O29: =N29 -> -385277.61
A30: Months of Runway Remaining | B30: =IF(B28>=0,"N/A",IF(B25<=0,0,ROUND(-B25/B28,1))) -> N/A | C30: =IF(C28>=0,"N/A",IF(C25<=0,0,ROUND(-C25/C28,1))) -> 0 | D30: =IF(D28>=0,"N/A",IF(D25<=0,0,ROUND(-D25/D28,1))) -> 0 | E30: =IF(E28>=0,"N/A",IF(E25<=0,0,ROUND(-E25/E28,1))) -> 0 | F30: =IF(F28>=0,"N/A",IF(F25<=0,0,ROUND(-F25/F28,1))) -> 0 | G30: =IF(G28>=0,"N/A",IF(G25<=0,0,ROUND(-G25/G28,1))) -> 0 | H30: =IF(H28>=0,"N/A",IF(H25<=0,0,ROUND(-H25/H28,1))) -> 0 | I30: =IF(I28>=0,"N/A",IF(I25<=0,0,ROUND(-I25/I28,1))) -> 0 | ... N30: =IF(N28>=0,"N/A",IF(N25<=0,0,ROUND(-N25/N28,1))) -> 0
A32: KEY CASH METRICS
A33: Metric | B33: Value | D33: Metric | E33: Value
A34: Pre-Launch Capital | B34: =Assumptions!B109 -> 240000 | D34: Year 1 Total Revenue (Cash In) | E34: =O7 -> 157261.25
A35: Year 1 Closing Cash Balance | B35: =N25 -> -385277.61 | D35: Year 1 Total Outflows | E35: =O19 -> 782538.86
A36: Peak Monthly Burn | B36: =MIN(C28:N28) -> -45339.167 | D36: Avg Monthly Burn (M1-M12) | E36: =AVERAGE(C28:N28) -> -35439.801
A38: Additional Funding Required | B38: =IF(N25<0,ABS(N25),0) -> 385277.61 | D38: Recommended Raise (Burn + 30% Buffer) | E38: =ROUND(B38*1.3,-3) -> 501000
A39: Recommended Raise (USD) | B39: =E38*Assumptions!$B$15 -> 706410 | D39: Runway After Raise (months) | E39: =ROUND(E38/ABS(E36),1) -> 14.1
A42: 5-YEAR CASH FLOW PROJECTION
A43: All figures in Jordanian Dinars (JOD) | Year 1 from Monthly P&L, Years 2-5 from Multi-Year Projections
A45: Line Item | B45: Year 1 | C45: Year 2 | D45: Year 3 | E45: Year 4 | F45: Year 5 | G45: 5-Yr Total
A46: CASH INFLOWS
A47: Seed Capital / Investment | B47: =Assumptions!B109 -> 240000 | C47: 0 | D47: 0 | E47: 0 | F47: 0 | G47: =SUM(B47:F47) -> 240000
A48: Subscription Revenue | B48: ='Multi-Year Projections'!B21 -> 157261.25 | C48: ='Multi-Year Projections'!C21 -> 961830.45 | D48: ='Multi-Year Projections'!D21 -> 2016142.1 | E48: ='Multi-Year Projections'!E21 -> 3572836.8 | F48: ='Multi-Year Projections'!F21 -> 5548246.7 | G48: =SUM(B48:F48) -> 12256317
A49: Ancillary Revenue | B49: ='Multi-Year Projections'!B22 -> 0 | C49: ='Multi-Year Projections'!C22 -> 28404 | D49: ='Multi-Year Projections'!D22 -> 139110 | E49: ='Multi-Year Projections'!E22 -> 422604 | F49: ='Multi-Year Projections'!F22 -> 991116 | G49: =SUM(B49:F49) -> 1581234
A50: Total Cash Inflows | B50: =SUM(B47:B49) -> 397261.25 | C50: =SUM(C47:C49) -> 990234.45 | D50: =SUM(D47:D49) -> 2155252.1 | E50: =SUM(E47:E49) -> 3995440.8 | F50: =SUM(F47:F49) -> 6539362.7 | G50: =SUM(B50:F50) -> 14077551
A52: CASH OUTFLOWS
...

Sheet Stress Tests
A1: WASEL — STRESS TESTS & SENSITIVITY ANALYSIS
A2: Impact analysis on Year 1 financials under adverse scenarios | Updated for 3-tier cohort model
A4: SCENARIO 1: TRANSITION CHURN SENSITIVITY
A5: Metric | B5: Base Case | C5: M0→50% churn | D5: M0→50%, M2+ 10% | E5: All churn 2x | F5: Notes
A6: M0→M1 Churn | B6: 0.25 | C6: 0.5 | D6: 0.5 | E6: 0.6 | F6: First payment wall is #1 risk
A7: M2+ Ongoing Churn | B7: 0.04 | C7: 0.05 | D7: 0.1 | E7: 0.1 | F7: Higher ongoing attrition
A8: Est. EoY Active Drivers | B8: ='Monthly P&L'!N11 -> 1479 | C8: 750 | D8: 500 | E8: 350 | F8: Churn is the #1 risk to the model
A9: Assessment | B9: Planned | C9: Manageable | D9: Concerning | E9: Critical | F9: Low pricing mitigates churn pressure
A11: SCENARIO 2: COMBINED DOWNSIDE STRESS TEST
A12: Stress Factor | B12: Base Case | C12: Downside | D12: Impact
A13: M0→M1 retention | B13: 75% survive | C13: 50% survive | D13: ~30% fewer drivers reach full pricing
A14: M2+ ongoing churn | B14: 4%/mo | C14: 10%/mo | D14: Active driver pool shrinks faster
A15: Mandatory insurance increase | B15: JD 8.65/driver/mo | C15: JD 20/driver/mo | D15: ~JD 120K additional cost/yr at scale
A16: Avg trips per driver per day | B16: 9 trips/day | C16: 5 trips/day | D16: Reduces driver income → may increase churn
A18: Combined Impact | B18: Base Case (Y1) | C18: All-Downside (Y1) | D18: Δ Change
A19: End-of-Year Active Drivers | B19: ='Monthly P&L'!N11 -> 1479 | C19: 350 | D19: =(C19-B19)/B19 -> -0.76335362
A20: Annual Revenue (JOD) | B20: ='Monthly P&L'!O23 -> 157261.25 | C20: 45000 | D20: =(C20-B20)/B20 -> -0.71385195
A21: Annual Net Income (JOD) | B21: ='Monthly P&L'!O53 -> -436944.27 | C21: -500000 | D21: =(C21-B21)/B21 -> 0.14431068
A22: Assessment | B22: Losses expected Y1; funded by seed | C22: CRITICAL: Requires bridge funding
A24: SCENARIO 3: SUBSCRIPTION FEE SENSITIVITY (BLENDED M2+ FEE)
A25: Metric | B25: JD 22/mo | C25: JD 27/mo | D25: JD 32.25 (Base) | E25: JD 38/mo | F25: JD 45/mo | G25: Notes
A26: Blended Monthly Fee (JOD) | B26: 22 | C26: 27 | D26: =Assumptions!B50 -> 32.25 | E26: 38 | F26: 45
A27: Est. Annual Revenue (JOD) | B27: =ROUND(B20*(B26/D26),0) -> 107279 | C27: =ROUND(B20*(C26/D26),0) -> 131661 | D27: =B20 -> 157261.25 | E27: =ROUND(B20*(E26/D26),0) -> 185300 | F27: =ROUND(B20*(F26/D26),0) -> 219434
A28: vs Base Case Revenue | B28: =(B27-D27)/D27 -> -0.31782941 | C28: =(C27-D27)/D27 -> -0.16278804 | D28: BASE | E28: =(E27-D27)/D27 -> 0.17829408 | F28: =(F27-D27)/D27 -> 0.39534691
A29: Fee as % of Driver Gross (~JD 520/mo) | B29: =B26/Assumptions!$B$11 -> 0.037606838 | C29: =C26/Assumptions!$B$11 -> 0.046153846 | D29: =D26/Assumptions!$B$11 -> 0.055128205 | E29: =E26/Assumptions!$B$11 -> 0.064957265 | F29: =F26/Assumptions!$B$11 -> 0.076923077 | G29: vs 30% at Uber/Careem
A31: SCENARIO 4: BREAK-EVEN BY ACTIVE M2+ DRIVER COUNT
A32: Active M2+ Drivers | B32: Monthly Revenue | C32: Monthly COGS | D32: Monthly OPEX | E32: Monthly P&L | F32: Status
A33: 500 | B33: =A33*Assumptions!$B$50 -> 16125 | C33: =A33*Assumptions!$B$59+Assumptions!$B$63+Assumptions!$B$64+Assumptions!$B$65 -> 5725 | D33: =Assumptions!$C$87+Assumptions!$B$69+Assumptions!$C$98+Assumptions!$C$85 -> 24066.667 | E33: =B33-C33-D33 -> -13666.667 | F33: ❌ Loss
A34: 1000 | B34: =A34*Assumptions!$B$50 -> 32250 | C34: =A34*Assumptions!$B$59+Assumptions!$B$63+Assumptions!$B$64+Assumptions!$B$65 -> 10050 | D34: =Assumptions!$C$87+Assumptions!$B$69+Assumptions!$C$98+Assumptions!$C$85 -> 24066.667 | E34: =B34-C34-D34 -> -1866.6667 | F34: ❌ Loss
A35: 1500 | B35: =A35*Assumptions!$B$50 -> 48375 | C35: =A35*Assumptions!$B$59+Assumptions!$B$63+Assumptions!$B$64+Assumptions!$B$65 -> 14375 | D35: =Assumptions!$C$87+Assumptions!$B$69+Assumptions!$C$98+Assumptions!$C$85 -> 24066.667 | E35: =B35-C35-D35 -> 9933.3333 | F35: =IF(E35>=0,"✅ Profitable","❌ Loss") -> ✅ Profitable
A36: 2000 | B36: =A36*Assumptions!$B$50 -> 64500 | C36: =A36*Assumptions!$B$59+Assumptions!$B$63+Assumptions!$B$64+Assumptions!$B$65 -> 18700 | D36: =Assumptions!$C$87+Assumptions!$B$69+Assumptions!$C$98+Assumptions!$C$85 -> 24066.667 | E36: =B36-C36-D36 -> 21733.333 | F36: =IF(E36>=0,"✅ Profitable","❌ Loss") -> ✅ Profitable
A37: 3000 | B37: =A37*Assumptions!$B$50 -> 96750 | C37: =A37*Assumptions!$B$59+Assumptions!$B$63+Assumptions!$B$64+Assumptions!$B$65 -> 27350 | D37: =Assumptions!$C$87+Assumptions!$B$69+Assumptions!$C$98+Assumptions!$C$85 -> 24066.667 | E37: =B37-C37-D37 -> 45333.333 | F37: =IF(E37>=0,"✅ Profitable","❌ Loss") -> ✅ Profitable
A38: 5000 | B38: =A38*Assumptions!$B$50 -> 161250 | C38: =A38*Assumptions!$B$59+Assumptions!$B$63+Assumptions!$B$64+Assumptions!$B$65 -> 44650 | D38: =Assumptions!$C$87+Assumptions!$B$69+Assumptions!$C$98+Assumptions!$C$85 -> 24066.667 | E38: =B38-C38-D38 -> 92533.333 | F38: =IF(E38>=0,"✅ Profitable","❌ Loss") -> ✅ Profitable
A40: Break-even requires ~1,200 active M2+ drivers paying full tier pricing (excl. M0/M1 onboarding drivers)
A42: SCENARIO 5: UNIT ECONOMICS SENSITIVITY (INVESTOR STRESS TEST)
A43: What happens to LTV/CAC when churn assumptions worsen?
A44: Mature Churn Rate (M6+) | B44: Avg Lifespan (Mo) | C44: LTV (JOD) | D44: LTV/CAC | E44: Survives? | F44: Assessment
A45: 0.025 | B45: 27 | C45: =B45*'Unit Economics'!$B$44 -> 476.85712 | D45: =C45/'Unit Economics'!$B$53 -> 10.596825 | E45: ✅ Yes — LTV/CAC >3x | F45: ✅ Base case — strong
A46: 0.05 | B46: 16 | C46: =B46*'Unit Economics'!$B$44 -> 282.582 | D46: =C46/'Unit Economics'!$B$53 -> 6.2796 | E46: ✅ Yes — LTV/CAC >3x | F46: ✅ Still healthy (>3x)
A47: 0.075 | B47: 11 | C47: =B47*'Unit Economics'!$B$44 -> 194.27513 | D47: =C47/'Unit Economics'!$B$53 -> 4.317225 | E47: ✅ Yes — LTV/CAC >3x | F47: ✅ Acceptable
...

Sheet Multi-Year Projections
A1: WASEL — 5-YEAR FINANCIAL PROJECTIONS
A2: All figures in Jordanian Dinars (JOD) | USD equivalent at 1 JOD = $1.41 | Cohort model
A4: Line Item | B4: Year 1 | C4: Year 2 | D4: Year 3 | E4: Year 4 | F4: Year 5 | G4: 5-Yr CAGR | H4: 5-Yr Total
A5: GROWTH ASSUMPTIONS
A6: Annual Net Driver Growth Rate | B6: N/A | C6: 1.2 | D6: 0.85 | E6: 0.6 | F6: 0.45
A7: Blended Fee Growth (Tier Mix Shift) | B7: N/A | C7: 0.05 | D7: 0.07 | E7: 0.05 | F7: 0.03
A8: Fixed OPEX Growth Rate | B8: N/A | C8: 0.3 | D8: 0.2 | E8: 0.15 | F8: 0.1
A9: Cities Operating | B9: 1 | C9: 3 | D9: 4 | E9: 6 | F9: 8
A10: Ancillary Revenue / Driver / Mo (JOD) | B10: 0 | C10: 1 | D10: 2.5 | E10: 4.5 | F10: 7
A13: KEY OPERATING METRICS
A14: Active Drivers (End of Year) | B14: ='Monthly P&L'!N11 -> 1479 | C14: =ROUND(B14*(1+C6),0) -> 3254 | D14: =ROUND(C14*(1+D6),0) -> 6020 | E14: =ROUND(D14*(1+E6),0) -> 9632 | F14: =ROUND(E14*(1+F6),0) -> 13966 | G14: =(F14/B14)^(1/4)-1 -> 0.75297598
A15: Avg Active Drivers (Annual) | B15: ='Monthly P&L'!O6/2 -> 1112 | C15: =ROUND((B14+C14)/2,0) -> 2367 | D15: =ROUND((C14+D14)/2,0) -> 4637 | E15: =ROUND((D14+E14)/2,0) -> 7826 | F15: =ROUND((E14+F14)/2,0) -> 11799
A16: Blended Monthly Fee / Driver (JOD) | B16: =Assumptions!B50 -> 32.25 | C16: =B16*(1+C7) -> 33.8625 | D16: =C16*(1+D7) -> 36.232875 | E16: =D16*(1+E7) -> 38.044519 | F16: =E16*(1+F7) -> 39.185854
A17: Team Headcount | B17: 5 | C17: 9 | D17: 15 | E17: 22 | F17: 30
A20: REVENUE
A21: Subscription Revenue | B21: ='Monthly P&L'!O23 -> 157261.25 | C21: =C15*C16*12 -> 961830.45 | D21: =D15*D16*12 -> 2016142.1 | E21: =E15*E16*12 -> 3572836.8 | F21: =F15*F16*12 -> 5548246.7 | H21: =SUM(B21:F21) -> 12256317
A22: Ancillary Revenue (Ads, Data, Partnerships) | B22: 0 | C22: =C15*C10*12 -> 28404 | D22: =D15*D10*12 -> 139110 | E22: =E15*E10*12 -> 422604 | F22: =F15*F10*12 -> 991116 | H22: =SUM(B22:F22) -> 1581234
A23: TOTAL REVENUE | B23: =B21+B22 -> 157261.25 | C23: =C21+C22 -> 990234.45 | D23: =D21+D22 -> 2155252.1 | E23: =E21+E22 -> 3995440.8 | F23: =F21+F22 -> 6539362.7 | G23: =(F23/B23)^(1/4)-1 -> 1.5393843 | H23: =SUM(B23:F23) -> 13837551
A24: YoY Revenue Growth | B24: N/A | C24: =(C23-B23)/B23 -> 5.2967479 | D24: =(D23-C23)/C23 -> 1.1765069 | E24: =(E23-D23)/D23 -> 0.85381601 | F24: =(F23-E23)/E23 -> 0.63670618
A27: COST OF REVENUE
A28: Payment Processing Fees | B28: ='Monthly P&L'!O26 -> 1651.2431 | C28: =C23*Assumptions!$B$13*Assumptions!$B$14 -> 10397.462 | D28: =D23*Assumptions!$B$13*Assumptions!$B$14 -> 22630.147 | E28: =E23*Assumptions!$B$13*Assumptions!$B$14 -> 41952.129 | F28: =F23*Assumptions!$B$13*Assumptions!$B$14 -> 68663.309 | H28: =SUM(B28:F28) -> 145294.29
A29: Insurance Program Costs | B29: ='Monthly P&L'!O27 -> 69719 | C29: =C15*Assumptions!$B$59*12 -> 245694.6 | D29: =D15*Assumptions!$B$59*12 -> 481320.6 | E29: =E15*Assumptions!$B$59*12 -> 812338.8 | F29: =F15*Assumptions!$B$59*12 -> 1224736.2 | H29: =SUM(B29:F29) -> 2833809.2
A30: Cloud & Tech Infrastructure | B30: ='Monthly P&L'!O28+'Monthly P&L'!O29+'Monthly P&L'!O30 -> 34438.3 | C30: =ROUND(B30*(C15/B15)^0.6,0) -> 54187 | D30: =ROUND(C30*(D15/C15)^0.6,0) -> 81118 | E30: =ROUND(D30*(E15/D15)^0.6,0) -> 111045 | F30: =ROUND(E30*(F15/E15)^0.6,0) -> 142063 | H30: =SUM(B30:F30) -> 422851.3
A31: Driver Onboarding & Verification | B31: ='Monthly P&L'!O31 -> 33360 | C31: =ROUND((C14-B14+C14*0.15)*Assumptions!$B$67,0) -> 33947 | D31: =ROUND((D14-C14+D14*0.12)*Assumptions!$B$67,0) -> 52326 | E31: =ROUND((E14-D14+E14*0.1)*Assumptions!$B$67,0) -> 68628 | F31: =ROUND((F14-E14+F14*0.08)*Assumptions!$B$67,0) -> 81769 | H31: =SUM(B31:F31) -> 270030
A32: Total Cost of Revenue | B32: =SUM(B28:B31) -> 139168.54 | C32: =SUM(C28:C31) -> 344226.06 | D32: =SUM(D28:D31) -> 637394.75 | E32: =SUM(E28:E31) -> 1033963.9 | F32: =SUM(F28:F31) -> 1517231.5 | H32: =SUM(B32:F32) -> 3671984.8
A34: GROSS PROFIT | B34: =B23-B32 -> 18092.707 | C34: =C23-C32 -> 646008.39 | D34: =D23-D32 -> 1517857.3 | E34: =E23-E32 -> 2961476.9 | F34: =F23-F32 -> 5022131.2 | H34: =SUM(B34:F34) -> 10165567
A35: Gross Margin % | B35: =IF(B23=0,0,B34/B23) -> 0.11504873 | C35: =IF(C23=0,0,C34/C23) -> 0.65237923 | D35: =IF(D23=0,0,D34/D23) -> 0.70425977 | E35: =IF(E23=0,0,E34/E23) -> 0.74121406 | F35: =IF(F23=0,0,F34/F23) -> 0.76798481
A37: OPERATING EXPENSES
A38: Team & Overhead (Salaries + Office) | B38: ='Monthly P&L'!O38 -> 90000 | C38: =ROUND(B38*1.3,0) -> 117000 | D38: =ROUND(C38*1.2,0) -> 140400 | E38: =ROUND(D38*1.15,0) -> 161460 | F38: =ROUND(E38*1.1,0) -> 177606 | H38: =SUM(B38:F38) -> 686466
A39: Customer Support | B39: ='Monthly P&L'!O39 -> 48360 | C39: =ROUND(B39*1.3,0) -> 62868 | D39: =ROUND(C39*1.2,0) -> 75442 | E39: =ROUND(D39*1.15,0) -> 86758 | F39: =ROUND(E39*1.1,0) -> 95434 | H39: =SUM(B39:F39) -> 368862
A40: Marketing — Driver Acquisition | B40: ='Monthly P&L'!O40 -> 66720 | C40: =ROUND(B40*1.3,0) -> 86736 | D40: =ROUND(C40*1.2,0) -> 104083 | E40: =ROUND(D40*1.15,0) -> 119695 | F40: =ROUND(E40*1.1,0) -> 131665 | H40: =SUM(B40:F40) -> 508899
A41: Rider Acquisition & Promos | B41: ='Monthly P&L'!O41 -> 36000 | C41: =ROUND(B41*1.3,0) -> 46800 | D41: =ROUND(C41*1.2,0) -> 56160 | E41: =ROUND(D41*1.15,0) -> 64584 | F41: =ROUND(E41*1.1,0) -> 71042 | H41: =SUM(B41:F41) -> 274586
A42: Regulatory & LTRC License Fee | B42: ='Monthly P&L'!O42 -> 158000 | C42: =ROUND(B42*1.3,0) -> 205400 | D42: =ROUND(C42*1.2,0) -> 246480 | E42: =ROUND(D42*1.15,0) -> 283452 | F42: =ROUND(E42*1.1,0) -> 311797 | H42: =SUM(B42:F42) -> 1205129
A43: Legal & Accounting | B43: ='Monthly P&L'!O43 -> 4800 | C43: =ROUND(B43*1.3,0) -> 6240 | D43: =ROUND(C43*1.2,0) -> 7488 | E43: =ROUND(D43*1.15,0) -> 8611 | F43: =ROUND(E43*1.1,0) -> 9472 | H43: =SUM(B43:F43) -> 36611
A44: OPEX Variance Adjustment (Y1 only) | B44: ='Monthly P&L'!O45-'Monthly P&L'!O44 -> 403880 | C44: 0 | D44: 0 | E44: 0 | F44: 0 | H44: =SUM(B44:F44) -> 403880
A45: Total Operating Expenses | B45: =SUM(B38:B44) -> 807760 | C45: =SUM(C38:C44) -> 525044 | D45: =SUM(D38:D44) -> 630053 | E45: =SUM(E38:E44) -> 724560 | F45: =SUM(F38:F44) -> 797016 | H45: =SUM(B45:F45) -> 3484433
A47: EBITDA | B47: =B34-B45 -> -789667.29 | C47: =C34-C45 -> 120964.39 | D47: =D34-D45 -> 887804.35 | E47: =E34-E45 -> 2236916.9 | F47: =F34-F45 -> 4225115.2 | H47: =SUM(B47:F47) -> 6681133.6
A48: EBITDA Margin % | B48: =IF(B23=0,0,B47/B23) -> -5.0213724 | C48: =IF(C23=0,0,C47/C23) -> 0.12215732 | D48: =IF(D23=0,0,D47/D23) -> 0.41192599 | E48: =IF(E23=0,0,E47/E23) -> 0.55986736 | F48: =IF(F23=0,0,F47/F23) -> 0.64610504
A50: Depreciation & Amortization | B50: ='Monthly P&L'!O50 -> 11666.667 | C50: =ROUND(B50*1.15,0) -> 13417 | D50: =ROUND(C50*1.1,0) -> 14759 | E50: =ROUND(D50*1.08,0) -> 15940 | F50: =ROUND(E50*1.05,0) -> 16737 | H50: =SUM(B50:F50) -> 72519.667
A51: Interest Expense | B51: ='Monthly P&L'!O51 -> 0 | C51: =ROUND(B51*0.85,0) -> 0 | D51: =ROUND(C51*0.7,0) -> 0 | E51: =ROUND(D51*0.5,0) -> 0 | F51: =ROUND(E51*0.3,0) -> 0 | H51: =SUM(B51:F51) -> 0
...

Sheet Executive Summary
A1: WASEL — EXECUTIVE SUMMARY
A2: Subscription-Based Ride-Hailing Platform | Amman, Jordan | 3-Tier Model with Graduated Onboarding
A4: COMPANY OVERVIEW
A6: Wasel is a subscription-based ride-hailing platform launching in Amman, Jordan. Unlike Uber and Careem, which charge
A7: drivers a 30% commission per ride, Wasel charges a low flat monthly subscription fee and lets drivers keep 100% of their
A8: fares. Drivers enter through a graduated onboarding program (free trial → ramp → full tier) to reduce friction and churn.
A10: MARKET OPPORTUNITY
A11: Metric | B11: Value | D11: Metric | E11: Value
A12: Target City | B12: Amman (4.5M metro) | D12: Jordan Ride-Hailing Market (2025) | E12: $61.5M
A13: Estimated Addressable Drivers | B13: =Assumptions!B30 -> 25000 | D13: Market Growth Rate (CAGR) | E13: 0.052
